[2024-10-29T17:29:19.437+0000] {local_task_job_runner.py:120} INFO - ::group::Pre task execution logs
[2024-10-29T17:29:19.469+0000] {taskinstance.py:2076} INFO - Dependencies all met for dep_context=non-requeueable deps ti=<TaskInstance: join_and_feature_engineer_all_data.join_and_merge manual__2024-10-29T14:30:15.385142+00:00 [queued]>
[2024-10-29T17:29:19.475+0000] {taskinstance.py:2076} INFO - Dependencies all met for dep_context=requeueable deps ti=<TaskInstance: join_and_feature_engineer_all_data.join_and_merge manual__2024-10-29T14:30:15.385142+00:00 [queued]>
[2024-10-29T17:29:19.476+0000] {taskinstance.py:2306} INFO - Starting attempt 4 of 4
[2024-10-29T17:29:19.485+0000] {taskinstance.py:2330} INFO - Executing <Task(PythonOperator): join_and_merge> on 2024-10-29 14:30:15.385142+00:00
[2024-10-29T17:29:19.497+0000] {logging_mixin.py:188} WARNING - /home/***/.local/lib/python3.12/site-packages/***/task/task_runner/standard_task_runner.py:61 DeprecationWarning: This process (pid=1573) is multi-threaded, use of fork() may lead to deadlocks in the child.
[2024-10-29T17:29:19.499+0000] {standard_task_runner.py:63} INFO - Started process 1578 to run task
[2024-10-29T17:29:19.499+0000] {standard_task_runner.py:90} INFO - Running: ['***', 'tasks', 'run', 'join_and_feature_engineer_all_data', 'join_and_merge', 'manual__2024-10-29T14:30:15.385142+00:00', '--job-id', '222', '--raw', '--subdir', 'DAGS_FOLDER/stock_data_pipelines.py', '--cfg-path', '/tmp/tmpxtawq69g']
[2024-10-29T17:29:19.503+0000] {standard_task_runner.py:91} INFO - Job 222: Subtask join_and_merge
[2024-10-29T17:29:19.526+0000] {logging_mixin.py:188} WARNING - /home/***/.local/lib/python3.12/site-packages/***/settings.py:195 DeprecationWarning: The sql_alchemy_conn option in [core] has been moved to the sql_alchemy_conn option in [database] - the old setting has been used, but please update your config.
[2024-10-29T17:29:19.576+0000] {task_command.py:426} INFO - Running <TaskInstance: join_and_feature_engineer_all_data.join_and_merge manual__2024-10-29T14:30:15.385142+00:00 [running]> on host a5e3407ec3e4
[2024-10-29T17:29:19.690+0000] {taskinstance.py:2648} INFO - Exporting env vars: AIRFLOW_CTX_DAG_OWNER='***' AIRFLOW_CTX_DAG_ID='join_and_feature_engineer_all_data' AIRFLOW_CTX_TASK_ID='join_and_merge' AIRFLOW_CTX_EXECUTION_DATE='2024-10-29T14:30:15.385142+00:00' AIRFLOW_CTX_TRY_NUMBER='4' AIRFLOW_CTX_DAG_RUN_ID='manual__2024-10-29T14:30:15.385142+00:00'
[2024-10-29T17:29:19.691+0000] {taskinstance.py:430} INFO - ::endgroup::
[2024-10-29T17:29:19.873+0000] {taskinstance.py:441} INFO - ::group::Post task execution logs
[2024-10-29T17:29:19.874+0000] {taskinstance.py:2905} ERROR - Task failed with exception
Traceback (most recent call last):
  File "/home/airflow/.local/lib/python3.12/site-packages/airflow/models/taskinstance.py", line 465, in _execute_task
    result = _execute_callable(context=context, **execute_callable_kwargs)
             ^^^^^^^^^^^^^^^^^^^^^^^^^^^^^^^^^^^^^^^^^^^^^^^^^^^^^^^^^^^^^
  File "/home/airflow/.local/lib/python3.12/site-packages/airflow/models/taskinstance.py", line 432, in _execute_callable
    return execute_callable(context=context, **execute_callable_kwargs)
           ^^^^^^^^^^^^^^^^^^^^^^^^^^^^^^^^^^^^^^^^^^^^^^^^^^^^^^^^^^^^
  File "/home/airflow/.local/lib/python3.12/site-packages/airflow/models/baseoperator.py", line 401, in wrapper
    return func(self, *args, **kwargs)
           ^^^^^^^^^^^^^^^^^^^^^^^^^^^
  File "/home/airflow/.local/lib/python3.12/site-packages/airflow/operators/python.py", line 235, in execute
    return_value = self.execute_callable()
                   ^^^^^^^^^^^^^^^^^^^^^^^
  File "/home/airflow/.local/lib/python3.12/site-packages/airflow/operators/python.py", line 252, in execute_callable
    return self.python_callable(*self.op_args, **self.op_kwargs)
           ^^^^^^^^^^^^^^^^^^^^^^^^^^^^^^^^^^^^^^^^^^^^^^^^^^^^^
  File "/opt/airflow/dags/utils/feature_engineer_and_join_data.py", line 11, in join_and_merge_datasets
    insider_transactions_data = insider_transactions_data.sort_values(by='transaction_date')
                                ^^^^^^^^^^^^^^^^^^^^^^^^^
UnboundLocalError: cannot access local variable 'insider_transactions_data' where it is not associated with a value
[2024-10-29T17:29:19.891+0000] {taskinstance.py:1206} INFO - Marking task as FAILED. dag_id=join_and_feature_engineer_all_data, task_id=join_and_merge, run_id=manual__2024-10-29T14:30:15.385142+00:00, execution_date=20241029T143015, start_date=20241029T172919, end_date=20241029T172919
[2024-10-29T17:29:19.902+0000] {standard_task_runner.py:110} ERROR - Failed to execute job 222 for task join_and_merge (cannot access local variable 'insider_transactions_data' where it is not associated with a value; 1578)
[2024-10-29T17:29:19.960+0000] {local_task_job_runner.py:240} INFO - Task exited with return code 1
[2024-10-29T17:29:19.983+0000] {taskinstance.py:3503} INFO - 0 downstream tasks scheduled from follow-on schedule check
[2024-10-29T17:29:19.986+0000] {local_task_job_runner.py:222} INFO - ::endgroup::
