[2024-10-29T17:39:12.839+0000] {local_task_job_runner.py:120} INFO - ::group::Pre task execution logs
[2024-10-29T17:39:12.875+0000] {taskinstance.py:2076} INFO - Dependencies all met for dep_context=non-requeueable deps ti=<TaskInstance: join_and_feature_engineer_all_data.join_and_merge manual__2024-10-29T14:30:15.385142+00:00 [queued]>
[2024-10-29T17:39:12.883+0000] {taskinstance.py:2076} INFO - Dependencies all met for dep_context=requeueable deps ti=<TaskInstance: join_and_feature_engineer_all_data.join_and_merge manual__2024-10-29T14:30:15.385142+00:00 [queued]>
[2024-10-29T17:39:12.884+0000] {taskinstance.py:2306} INFO - Starting attempt 7 of 7
[2024-10-29T17:39:12.895+0000] {taskinstance.py:2330} INFO - Executing <Task(PythonOperator): join_and_merge> on 2024-10-29 14:30:15.385142+00:00
[2024-10-29T17:39:12.909+0000] {logging_mixin.py:188} WARNING - /home/***/.local/lib/python3.12/site-packages/***/task/task_runner/standard_task_runner.py:61 DeprecationWarning: This process (pid=2282) is multi-threaded, use of fork() may lead to deadlocks in the child.
[2024-10-29T17:39:12.911+0000] {standard_task_runner.py:63} INFO - Started process 2287 to run task
[2024-10-29T17:39:12.915+0000] {standard_task_runner.py:90} INFO - Running: ['***', 'tasks', 'run', 'join_and_feature_engineer_all_data', 'join_and_merge', 'manual__2024-10-29T14:30:15.385142+00:00', '--job-id', '225', '--raw', '--subdir', 'DAGS_FOLDER/stock_data_pipelines.py', '--cfg-path', '/tmp/tmpki721urj']
[2024-10-29T17:39:12.919+0000] {standard_task_runner.py:91} INFO - Job 225: Subtask join_and_merge
[2024-10-29T17:39:12.938+0000] {logging_mixin.py:188} WARNING - /home/***/.local/lib/python3.12/site-packages/***/settings.py:195 DeprecationWarning: The sql_alchemy_conn option in [core] has been moved to the sql_alchemy_conn option in [database] - the old setting has been used, but please update your config.
[2024-10-29T17:39:12.986+0000] {task_command.py:426} INFO - Running <TaskInstance: join_and_feature_engineer_all_data.join_and_merge manual__2024-10-29T14:30:15.385142+00:00 [running]> on host a5e3407ec3e4
[2024-10-29T17:39:13.088+0000] {taskinstance.py:2648} INFO - Exporting env vars: AIRFLOW_CTX_DAG_OWNER='***' AIRFLOW_CTX_DAG_ID='join_and_feature_engineer_all_data' AIRFLOW_CTX_TASK_ID='join_and_merge' AIRFLOW_CTX_EXECUTION_DATE='2024-10-29T14:30:15.385142+00:00' AIRFLOW_CTX_TRY_NUMBER='7' AIRFLOW_CTX_DAG_RUN_ID='manual__2024-10-29T14:30:15.385142+00:00'
[2024-10-29T17:39:13.090+0000] {taskinstance.py:430} INFO - ::endgroup::
[2024-10-29T17:39:13.296+0000] {taskinstance.py:441} INFO - ::group::Post task execution logs
[2024-10-29T17:39:13.297+0000] {taskinstance.py:2905} ERROR - Task failed with exception
Traceback (most recent call last):
  File "/home/airflow/.local/lib/python3.12/site-packages/pandas/core/indexes/base.py", line 3791, in get_loc
    return self._engine.get_loc(casted_key)
           ^^^^^^^^^^^^^^^^^^^^^^^^^^^^^^^^
  File "index.pyx", line 152, in pandas._libs.index.IndexEngine.get_loc
  File "index.pyx", line 181, in pandas._libs.index.IndexEngine.get_loc
  File "pandas/_libs/hashtable_class_helper.pxi", line 7080, in pandas._libs.hashtable.PyObjectHashTable.get_item
  File "pandas/_libs/hashtable_class_helper.pxi", line 7088, in pandas._libs.hashtable.PyObjectHashTable.get_item
KeyError: 'ticker'

The above exception was the direct cause of the following exception:

Traceback (most recent call last):
  File "/home/airflow/.local/lib/python3.12/site-packages/airflow/models/taskinstance.py", line 465, in _execute_task
    result = _execute_callable(context=context, **execute_callable_kwargs)
             ^^^^^^^^^^^^^^^^^^^^^^^^^^^^^^^^^^^^^^^^^^^^^^^^^^^^^^^^^^^^^
  File "/home/airflow/.local/lib/python3.12/site-packages/airflow/models/taskinstance.py", line 432, in _execute_callable
    return execute_callable(context=context, **execute_callable_kwargs)
           ^^^^^^^^^^^^^^^^^^^^^^^^^^^^^^^^^^^^^^^^^^^^^^^^^^^^^^^^^^^^
  File "/home/airflow/.local/lib/python3.12/site-packages/airflow/models/baseoperator.py", line 401, in wrapper
    return func(self, *args, **kwargs)
           ^^^^^^^^^^^^^^^^^^^^^^^^^^^
  File "/home/airflow/.local/lib/python3.12/site-packages/airflow/operators/python.py", line 235, in execute
    return_value = self.execute_callable()
                   ^^^^^^^^^^^^^^^^^^^^^^^
  File "/home/airflow/.local/lib/python3.12/site-packages/airflow/operators/python.py", line 252, in execute_callable
    return self.python_callable(*self.op_args, **self.op_kwargs)
           ^^^^^^^^^^^^^^^^^^^^^^^^^^^^^^^^^^^^^^^^^^^^^^^^^^^^^
  File "/opt/airflow/dags/utils/feature_engineer_and_join_data.py", line 23, in join_and_merge_datasets
    technical_indicators_data['symbol'] = technical_indicators_data['ticker'].str.upper()
                                          ~~~~~~~~~~~~~~~~~~~~~~~~~^^^^^^^^^^
  File "/home/airflow/.local/lib/python3.12/site-packages/pandas/core/frame.py", line 3893, in __getitem__
    indexer = self.columns.get_loc(key)
              ^^^^^^^^^^^^^^^^^^^^^^^^^
  File "/home/airflow/.local/lib/python3.12/site-packages/pandas/core/indexes/base.py", line 3798, in get_loc
    raise KeyError(key) from err
KeyError: 'ticker'
[2024-10-29T17:39:13.329+0000] {taskinstance.py:1206} INFO - Marking task as FAILED. dag_id=join_and_feature_engineer_all_data, task_id=join_and_merge, run_id=manual__2024-10-29T14:30:15.385142+00:00, execution_date=20241029T143015, start_date=20241029T173912, end_date=20241029T173913
[2024-10-29T17:39:13.341+0000] {standard_task_runner.py:110} ERROR - Failed to execute job 225 for task join_and_merge ('ticker'; 2287)
[2024-10-29T17:39:13.412+0000] {local_task_job_runner.py:240} INFO - Task exited with return code 1
[2024-10-29T17:39:13.439+0000] {taskinstance.py:3503} INFO - 0 downstream tasks scheduled from follow-on schedule check
[2024-10-29T17:39:13.444+0000] {local_task_job_runner.py:222} INFO - ::endgroup::
