[2024-10-29T17:27:57.609+0000] {local_task_job_runner.py:120} INFO - ::group::Pre task execution logs
[2024-10-29T17:27:57.670+0000] {taskinstance.py:2076} INFO - Dependencies all met for dep_context=non-requeueable deps ti=<TaskInstance: join_and_feature_engineer_all_data.join_and_merge manual__2024-10-29T14:30:15.385142+00:00 [queued]>
[2024-10-29T17:27:57.680+0000] {taskinstance.py:2076} INFO - Dependencies all met for dep_context=requeueable deps ti=<TaskInstance: join_and_feature_engineer_all_data.join_and_merge manual__2024-10-29T14:30:15.385142+00:00 [queued]>
[2024-10-29T17:27:57.681+0000] {taskinstance.py:2306} INFO - Starting attempt 3 of 3
[2024-10-29T17:27:57.693+0000] {taskinstance.py:2330} INFO - Executing <Task(PythonOperator): join_and_merge> on 2024-10-29 14:30:15.385142+00:00
[2024-10-29T17:27:57.714+0000] {logging_mixin.py:188} WARNING - /home/***/.local/lib/python3.12/site-packages/***/task/task_runner/standard_task_runner.py:61 DeprecationWarning: This process (pid=1459) is multi-threaded, use of fork() may lead to deadlocks in the child.
[2024-10-29T17:27:57.713+0000] {standard_task_runner.py:90} INFO - Running: ['***', 'tasks', 'run', 'join_and_feature_engineer_all_data', 'join_and_merge', 'manual__2024-10-29T14:30:15.385142+00:00', '--job-id', '221', '--raw', '--subdir', 'DAGS_FOLDER/stock_data_pipelines.py', '--cfg-path', '/tmp/tmph__99pym']
[2024-10-29T17:27:57.718+0000] {standard_task_runner.py:63} INFO - Started process 1471 to run task
[2024-10-29T17:27:57.719+0000] {standard_task_runner.py:91} INFO - Job 221: Subtask join_and_merge
[2024-10-29T17:27:57.749+0000] {logging_mixin.py:188} WARNING - /home/***/.local/lib/python3.12/site-packages/***/settings.py:195 DeprecationWarning: The sql_alchemy_conn option in [core] has been moved to the sql_alchemy_conn option in [database] - the old setting has been used, but please update your config.
[2024-10-29T17:27:57.820+0000] {task_command.py:426} INFO - Running <TaskInstance: join_and_feature_engineer_all_data.join_and_merge manual__2024-10-29T14:30:15.385142+00:00 [running]> on host a5e3407ec3e4
[2024-10-29T17:27:57.924+0000] {taskinstance.py:2648} INFO - Exporting env vars: AIRFLOW_CTX_DAG_OWNER='***' AIRFLOW_CTX_DAG_ID='join_and_feature_engineer_all_data' AIRFLOW_CTX_TASK_ID='join_and_merge' AIRFLOW_CTX_EXECUTION_DATE='2024-10-29T14:30:15.385142+00:00' AIRFLOW_CTX_TRY_NUMBER='3' AIRFLOW_CTX_DAG_RUN_ID='manual__2024-10-29T14:30:15.385142+00:00'
[2024-10-29T17:27:57.927+0000] {taskinstance.py:430} INFO - ::endgroup::
[2024-10-29T17:27:58.131+0000] {taskinstance.py:441} INFO - ::group::Post task execution logs
[2024-10-29T17:27:58.132+0000] {taskinstance.py:2905} ERROR - Task failed with exception
Traceback (most recent call last):
  File "/home/airflow/.local/lib/python3.12/site-packages/airflow/models/taskinstance.py", line 465, in _execute_task
    result = _execute_callable(context=context, **execute_callable_kwargs)
             ^^^^^^^^^^^^^^^^^^^^^^^^^^^^^^^^^^^^^^^^^^^^^^^^^^^^^^^^^^^^^
  File "/home/airflow/.local/lib/python3.12/site-packages/airflow/models/taskinstance.py", line 432, in _execute_callable
    return execute_callable(context=context, **execute_callable_kwargs)
           ^^^^^^^^^^^^^^^^^^^^^^^^^^^^^^^^^^^^^^^^^^^^^^^^^^^^^^^^^^^^
  File "/home/airflow/.local/lib/python3.12/site-packages/airflow/models/baseoperator.py", line 401, in wrapper
    return func(self, *args, **kwargs)
           ^^^^^^^^^^^^^^^^^^^^^^^^^^^
  File "/home/airflow/.local/lib/python3.12/site-packages/airflow/operators/python.py", line 235, in execute
    return_value = self.execute_callable()
                   ^^^^^^^^^^^^^^^^^^^^^^^
  File "/home/airflow/.local/lib/python3.12/site-packages/airflow/operators/python.py", line 252, in execute_callable
    return self.python_callable(*self.op_args, **self.op_kwargs)
           ^^^^^^^^^^^^^^^^^^^^^^^^^^^^^^^^^^^^^^^^^^^^^^^^^^^^^
  File "/opt/airflow/dags/utils/feature_engineer_and_join_data.py", line 13, in join_and_merge_datasets
    merged_df = pd.merge_asof(stock_data, insider_transaction_data,
                ^^^^^^^^^^^^^^^^^^^^^^^^^^^^^^^^^^^^^^^^^^^^^^^^^^^
  File "/home/airflow/.local/lib/python3.12/site-packages/pandas/core/reshape/merge.py", line 705, in merge_asof
    return op.get_result()
           ^^^^^^^^^^^^^^^
  File "/home/airflow/.local/lib/python3.12/site-packages/pandas/core/reshape/merge.py", line 1852, in get_result
    join_index, left_indexer, right_indexer = self._get_join_info()
                                              ^^^^^^^^^^^^^^^^^^^^^
  File "/home/airflow/.local/lib/python3.12/site-packages/pandas/core/reshape/merge.py", line 1133, in _get_join_info
    (left_indexer, right_indexer) = self._get_join_indexers()
                                    ^^^^^^^^^^^^^^^^^^^^^^^^^
  File "/home/airflow/.local/lib/python3.12/site-packages/pandas/core/reshape/merge.py", line 2176, in _get_join_indexers
    right_values = self._convert_values_for_libjoin(right_values, "right")
                   ^^^^^^^^^^^^^^^^^^^^^^^^^^^^^^^^^^^^^^^^^^^^^^^^^^^^^^^
  File "/home/airflow/.local/lib/python3.12/site-packages/pandas/core/reshape/merge.py", line 2097, in _convert_values_for_libjoin
    raise ValueError(f"{side} keys must be sorted")
ValueError: right keys must be sorted
[2024-10-29T17:27:58.153+0000] {taskinstance.py:1206} INFO - Marking task as FAILED. dag_id=join_and_feature_engineer_all_data, task_id=join_and_merge, run_id=manual__2024-10-29T14:30:15.385142+00:00, execution_date=20241029T143015, start_date=20241029T172757, end_date=20241029T172758
[2024-10-29T17:27:58.167+0000] {standard_task_runner.py:110} ERROR - Failed to execute job 221 for task join_and_merge (right keys must be sorted; 1471)
[2024-10-29T17:27:58.220+0000] {local_task_job_runner.py:240} INFO - Task exited with return code 1
[2024-10-29T17:27:58.249+0000] {taskinstance.py:3503} INFO - 0 downstream tasks scheduled from follow-on schedule check
[2024-10-29T17:27:58.254+0000] {local_task_job_runner.py:222} INFO - ::endgroup::
