[2024-10-28T21:39:53.516+0000] {local_task_job_runner.py:120} INFO - ::group::Pre task execution logs
[2024-10-28T21:39:53.537+0000] {taskinstance.py:2076} INFO - Dependencies all met for dep_context=non-requeueable deps ti=<TaskInstance: fetch_and_clean_news_sentiment_data.clean_news_sentiment_data manual__2024-10-28T21:29:07.834630+00:00 [queued]>
[2024-10-28T21:39:53.542+0000] {taskinstance.py:2076} INFO - Dependencies all met for dep_context=requeueable deps ti=<TaskInstance: fetch_and_clean_news_sentiment_data.clean_news_sentiment_data manual__2024-10-28T21:29:07.834630+00:00 [queued]>
[2024-10-28T21:39:53.543+0000] {taskinstance.py:2306} INFO - Starting attempt 4 of 4
[2024-10-28T21:39:53.549+0000] {taskinstance.py:2330} INFO - Executing <Task(PythonOperator): clean_news_sentiment_data> on 2024-10-28 21:29:07.834630+00:00
[2024-10-28T21:39:53.556+0000] {logging_mixin.py:188} WARNING - /home/***/.local/lib/python3.12/site-packages/***/task/task_runner/standard_task_runner.py:61 DeprecationWarning: This process (pid=19684) is multi-threaded, use of fork() may lead to deadlocks in the child.
[2024-10-28T21:39:53.558+0000] {standard_task_runner.py:63} INFO - Started process 19686 to run task
[2024-10-28T21:39:53.557+0000] {standard_task_runner.py:90} INFO - Running: ['***', 'tasks', 'run', 'fetch_and_clean_news_sentiment_data', 'clean_news_sentiment_data', 'manual__2024-10-28T21:29:07.834630+00:00', '--job-id', '85', '--raw', '--subdir', 'DAGS_FOLDER/stock_data_pipelines.py', '--cfg-path', '/tmp/tmpbcg7igd7']
[2024-10-28T21:39:53.560+0000] {standard_task_runner.py:91} INFO - Job 85: Subtask clean_news_sentiment_data
[2024-10-28T21:39:53.574+0000] {logging_mixin.py:188} WARNING - /home/***/.local/lib/python3.12/site-packages/***/settings.py:195 DeprecationWarning: The sql_alchemy_conn option in [core] has been moved to the sql_alchemy_conn option in [database] - the old setting has been used, but please update your config.
[2024-10-28T21:39:53.605+0000] {task_command.py:426} INFO - Running <TaskInstance: fetch_and_clean_news_sentiment_data.clean_news_sentiment_data manual__2024-10-28T21:29:07.834630+00:00 [running]> on host 66a068bd0545
[2024-10-28T21:39:53.665+0000] {taskinstance.py:2648} INFO - Exporting env vars: AIRFLOW_CTX_DAG_OWNER='***' AIRFLOW_CTX_DAG_ID='fetch_and_clean_news_sentiment_data' AIRFLOW_CTX_TASK_ID='clean_news_sentiment_data' AIRFLOW_CTX_EXECUTION_DATE='2024-10-28T21:29:07.834630+00:00' AIRFLOW_CTX_TRY_NUMBER='4' AIRFLOW_CTX_DAG_RUN_ID='manual__2024-10-28T21:29:07.834630+00:00'
[2024-10-28T21:39:53.666+0000] {taskinstance.py:430} INFO - ::endgroup::
[2024-10-28T21:39:53.685+0000] {taskinstance.py:441} INFO - ::group::Post task execution logs
[2024-10-28T21:39:53.686+0000] {taskinstance.py:2905} ERROR - Task failed with exception
Traceback (most recent call last):
  File "/home/airflow/.local/lib/python3.12/site-packages/airflow/models/taskinstance.py", line 465, in _execute_task
    result = _execute_callable(context=context, **execute_callable_kwargs)
             ^^^^^^^^^^^^^^^^^^^^^^^^^^^^^^^^^^^^^^^^^^^^^^^^^^^^^^^^^^^^^
  File "/home/airflow/.local/lib/python3.12/site-packages/airflow/models/taskinstance.py", line 432, in _execute_callable
    return execute_callable(context=context, **execute_callable_kwargs)
           ^^^^^^^^^^^^^^^^^^^^^^^^^^^^^^^^^^^^^^^^^^^^^^^^^^^^^^^^^^^^
  File "/home/airflow/.local/lib/python3.12/site-packages/airflow/models/baseoperator.py", line 401, in wrapper
    return func(self, *args, **kwargs)
           ^^^^^^^^^^^^^^^^^^^^^^^^^^^
  File "/home/airflow/.local/lib/python3.12/site-packages/airflow/operators/python.py", line 235, in execute
    return_value = self.execute_callable()
                   ^^^^^^^^^^^^^^^^^^^^^^^
  File "/home/airflow/.local/lib/python3.12/site-packages/airflow/operators/python.py", line 252, in execute_callable
    return self.python_callable(*self.op_args, **self.op_kwargs)
           ^^^^^^^^^^^^^^^^^^^^^^^^^^^^^^^^^^^^^^^^^^^^^^^^^^^^^
  File "/opt/airflow/dags/utils/stock_data_elt.py", line 194, in clean_news_sentiment_data
    df['time_published'] = pd.to_datetime(df['time_published'].str[:8] + ' ' + df['time_published'].str[-6:])
                                          ~~^^^^^^^^^^^^^^^^^^
TypeError: 'NoneType' object is not subscriptable
[2024-10-28T21:39:53.696+0000] {taskinstance.py:1206} INFO - Marking task as FAILED. dag_id=fetch_and_clean_news_sentiment_data, task_id=clean_news_sentiment_data, run_id=manual__2024-10-28T21:29:07.834630+00:00, execution_date=20241028T212907, start_date=20241028T213953, end_date=20241028T213953
[2024-10-28T21:39:53.703+0000] {standard_task_runner.py:110} ERROR - Failed to execute job 85 for task clean_news_sentiment_data ('NoneType' object is not subscriptable; 19686)
[2024-10-28T21:39:53.733+0000] {local_task_job_runner.py:240} INFO - Task exited with return code 1
[2024-10-28T21:39:53.749+0000] {taskinstance.py:3503} INFO - 0 downstream tasks scheduled from follow-on schedule check
[2024-10-28T21:39:53.751+0000] {local_task_job_runner.py:222} INFO - ::endgroup::
