[2024-10-28T16:50:26.259+0000] {local_task_job_runner.py:120} INFO - ::group::Pre task execution logs
[2024-10-28T16:50:26.291+0000] {taskinstance.py:2076} INFO - Dependencies all met for dep_context=non-requeueable deps ti=<TaskInstance: fetch_and_clean_insider_transaction_data.store_insider_transaction_data_s3 manual__2024-10-28T15:53:59.592313+00:00 [queued]>
[2024-10-28T16:50:26.298+0000] {taskinstance.py:2076} INFO - Dependencies all met for dep_context=requeueable deps ti=<TaskInstance: fetch_and_clean_insider_transaction_data.store_insider_transaction_data_s3 manual__2024-10-28T15:53:59.592313+00:00 [queued]>
[2024-10-28T16:50:26.298+0000] {taskinstance.py:2306} INFO - Starting attempt 1 of 1
[2024-10-28T16:50:26.307+0000] {taskinstance.py:2330} INFO - Executing <Task(PythonOperator): store_insider_transaction_data_s3> on 2024-10-28 15:53:59.592313+00:00
[2024-10-28T16:50:26.315+0000] {logging_mixin.py:188} WARNING - /home/***/.local/lib/python3.12/site-packages/***/task/task_runner/standard_task_runner.py:61 DeprecationWarning: This process (pid=1912) is multi-threaded, use of fork() may lead to deadlocks in the child.
[2024-10-28T16:50:26.316+0000] {standard_task_runner.py:63} INFO - Started process 1914 to run task
[2024-10-28T16:50:26.316+0000] {standard_task_runner.py:90} INFO - Running: ['***', 'tasks', 'run', 'fetch_and_clean_insider_transaction_data', 'store_insider_transaction_data_s3', 'manual__2024-10-28T15:53:59.592313+00:00', '--job-id', '61', '--raw', '--subdir', 'DAGS_FOLDER/stock_data_pipelines.py', '--cfg-path', '/tmp/tmpd9oz3eji']
[2024-10-28T16:50:26.320+0000] {standard_task_runner.py:91} INFO - Job 61: Subtask store_insider_transaction_data_s3
[2024-10-28T16:50:26.338+0000] {logging_mixin.py:188} WARNING - /home/***/.local/lib/python3.12/site-packages/***/settings.py:195 DeprecationWarning: The sql_alchemy_conn option in [core] has been moved to the sql_alchemy_conn option in [database] - the old setting has been used, but please update your config.
[2024-10-28T16:50:26.390+0000] {task_command.py:426} INFO - Running <TaskInstance: fetch_and_clean_insider_transaction_data.store_insider_transaction_data_s3 manual__2024-10-28T15:53:59.592313+00:00 [running]> on host 66a068bd0545
[2024-10-28T16:50:26.477+0000] {taskinstance.py:2648} INFO - Exporting env vars: AIRFLOW_CTX_DAG_OWNER='***' AIRFLOW_CTX_DAG_ID='fetch_and_clean_insider_transaction_data' AIRFLOW_CTX_TASK_ID='store_insider_transaction_data_s3' AIRFLOW_CTX_EXECUTION_DATE='2024-10-28T15:53:59.592313+00:00' AIRFLOW_CTX_TRY_NUMBER='1' AIRFLOW_CTX_DAG_RUN_ID='manual__2024-10-28T15:53:59.592313+00:00'
[2024-10-28T16:50:26.479+0000] {taskinstance.py:430} INFO - ::endgroup::
[2024-10-28T16:50:26.561+0000] {credentials.py:1147} INFO - Found credentials in environment variables.
[2024-10-28T16:50:26.673+0000] {taskinstance.py:441} INFO - ::group::Post task execution logs
[2024-10-28T16:50:26.674+0000] {taskinstance.py:2905} ERROR - Task failed with exception
Traceback (most recent call last):
  File "/home/airflow/.local/lib/python3.12/site-packages/airflow/models/taskinstance.py", line 465, in _execute_task
    result = _execute_callable(context=context, **execute_callable_kwargs)
             ^^^^^^^^^^^^^^^^^^^^^^^^^^^^^^^^^^^^^^^^^^^^^^^^^^^^^^^^^^^^^
  File "/home/airflow/.local/lib/python3.12/site-packages/airflow/models/taskinstance.py", line 432, in _execute_callable
    return execute_callable(context=context, **execute_callable_kwargs)
           ^^^^^^^^^^^^^^^^^^^^^^^^^^^^^^^^^^^^^^^^^^^^^^^^^^^^^^^^^^^^
  File "/home/airflow/.local/lib/python3.12/site-packages/airflow/models/baseoperator.py", line 401, in wrapper
    return func(self, *args, **kwargs)
           ^^^^^^^^^^^^^^^^^^^^^^^^^^^
  File "/home/airflow/.local/lib/python3.12/site-packages/airflow/operators/python.py", line 235, in execute
    return_value = self.execute_callable()
                   ^^^^^^^^^^^^^^^^^^^^^^^
  File "/home/airflow/.local/lib/python3.12/site-packages/airflow/operators/python.py", line 252, in execute_callable
    return self.python_callable(*self.op_args, **self.op_kwargs)
           ^^^^^^^^^^^^^^^^^^^^^^^^^^^^^^^^^^^^^^^^^^^^^^^^^^^^^
  File "/opt/airflow/dags/utils/s3_helper.py", line 27, in store_insider_transaction_data_in_s3
    save_to_s3(df, file_name)
  File "/opt/airflow/dags/utils/s3_helper.py", line 17, in save_to_s3
    s3.upload_file(local_path, bucket_name, file_name)
  File "/home/airflow/.local/lib/python3.12/site-packages/boto3/s3/inject.py", line 145, in upload_file
    return transfer.upload_file(
           ^^^^^^^^^^^^^^^^^^^^^
  File "/home/airflow/.local/lib/python3.12/site-packages/boto3/s3/transfer.py", line 371, in upload_file
    future.result()
  File "/home/airflow/.local/lib/python3.12/site-packages/s3transfer/futures.py", line 103, in result
    return self._coordinator.result()
           ^^^^^^^^^^^^^^^^^^^^^^^^^^
  File "/home/airflow/.local/lib/python3.12/site-packages/s3transfer/futures.py", line 266, in result
    raise self._exception
  File "/home/airflow/.local/lib/python3.12/site-packages/s3transfer/tasks.py", line 269, in _main
    self._submit(transfer_future=transfer_future, **kwargs)
  File "/home/airflow/.local/lib/python3.12/site-packages/s3transfer/upload.py", line 591, in _submit
    upload_input_manager.provide_transfer_size(transfer_future)
  File "/home/airflow/.local/lib/python3.12/site-packages/s3transfer/upload.py", line 244, in provide_transfer_size
    self._osutil.get_file_size(transfer_future.meta.call_args.fileobj)
  File "/home/airflow/.local/lib/python3.12/site-packages/s3transfer/utils.py", line 256, in get_file_size
    return os.path.getsize(filename)
           ^^^^^^^^^^^^^^^^^^^^^^^^^
  File "<frozen genericpath>", line 62, in getsize
FileNotFoundError: [Errno 2] No such file or directory: '/opt/airflow/data/bronze/insider_transaction_data.parquet'
[2024-10-28T16:50:26.690+0000] {taskinstance.py:1206} INFO - Marking task as FAILED. dag_id=fetch_and_clean_insider_transaction_data, task_id=store_insider_transaction_data_s3, run_id=manual__2024-10-28T15:53:59.592313+00:00, execution_date=20241028T155359, start_date=20241028T165026, end_date=20241028T165026
[2024-10-28T16:50:26.699+0000] {standard_task_runner.py:110} ERROR - Failed to execute job 61 for task store_insider_transaction_data_s3 ([Errno 2] No such file or directory: '/opt/airflow/data/bronze/insider_transaction_data.parquet'; 1914)
[2024-10-28T16:50:26.737+0000] {local_task_job_runner.py:240} INFO - Task exited with return code 1
[2024-10-28T16:50:26.752+0000] {local_task_job_runner.py:222} INFO - ::endgroup::
