[2024-10-28T16:14:21.405+0000] {local_task_job_runner.py:120} INFO - ::group::Pre task execution logs
[2024-10-28T16:14:21.450+0000] {taskinstance.py:2076} INFO - Dependencies all met for dep_context=non-requeueable deps ti=<TaskInstance: fetch_and_clean_insider_transaction_data.fetch_insider_transaction_data manual__2024-10-28T15:53:59.592313+00:00 [queued]>
[2024-10-28T16:14:21.460+0000] {taskinstance.py:2076} INFO - Dependencies all met for dep_context=requeueable deps ti=<TaskInstance: fetch_and_clean_insider_transaction_data.fetch_insider_transaction_data manual__2024-10-28T15:53:59.592313+00:00 [queued]>
[2024-10-28T16:14:21.461+0000] {taskinstance.py:2306} INFO - Starting attempt 9 of 9
[2024-10-28T16:14:21.475+0000] {taskinstance.py:2330} INFO - Executing <Task(PythonOperator): fetch_insider_transaction_data> on 2024-10-28 15:53:59.592313+00:00
[2024-10-28T16:14:21.492+0000] {logging_mixin.py:188} WARNING - /home/***/.local/lib/python3.12/site-packages/***/task/task_runner/standard_task_runner.py:61 DeprecationWarning: This process (pid=198) is multi-threaded, use of fork() may lead to deadlocks in the child.
[2024-10-28T16:14:21.496+0000] {standard_task_runner.py:63} INFO - Started process 208 to run task
[2024-10-28T16:14:21.497+0000] {standard_task_runner.py:90} INFO - Running: ['***', 'tasks', 'run', 'fetch_and_clean_insider_transaction_data', 'fetch_insider_transaction_data', 'manual__2024-10-28T15:53:59.592313+00:00', '--job-id', '53', '--raw', '--subdir', 'DAGS_FOLDER/stock_data_pipelines.py', '--cfg-path', '/tmp/tmp52787t5b']
[2024-10-28T16:14:21.504+0000] {standard_task_runner.py:91} INFO - Job 53: Subtask fetch_insider_transaction_data
[2024-10-28T16:14:21.528+0000] {logging_mixin.py:188} WARNING - /home/***/.local/lib/python3.12/site-packages/***/settings.py:195 DeprecationWarning: The sql_alchemy_conn option in [core] has been moved to the sql_alchemy_conn option in [database] - the old setting has been used, but please update your config.
[2024-10-28T16:14:21.584+0000] {task_command.py:426} INFO - Running <TaskInstance: fetch_and_clean_insider_transaction_data.fetch_insider_transaction_data manual__2024-10-28T15:53:59.592313+00:00 [running]> on host 66a068bd0545
[2024-10-28T16:14:21.691+0000] {taskinstance.py:2648} INFO - Exporting env vars: AIRFLOW_CTX_DAG_OWNER='***' AIRFLOW_CTX_DAG_ID='fetch_and_clean_insider_transaction_data' AIRFLOW_CTX_TASK_ID='fetch_insider_transaction_data' AIRFLOW_CTX_EXECUTION_DATE='2024-10-28T15:53:59.592313+00:00' AIRFLOW_CTX_TRY_NUMBER='9' AIRFLOW_CTX_DAG_RUN_ID='manual__2024-10-28T15:53:59.592313+00:00'
[2024-10-28T16:14:21.693+0000] {taskinstance.py:430} INFO - ::endgroup::
[2024-10-28T16:14:22.565+0000] {logging_mixin.py:188} INFO - {'Information': 'Thank you for using Alpha Vantage! Our standard API rate limit is 25 requests per day. Please subscribe to any of the premium plans at https://www.alphavantage.co/premium/ to instantly remove all daily rate limits.'}
[2024-10-28T16:14:22.567+0000] {taskinstance.py:441} INFO - ::group::Post task execution logs
[2024-10-28T16:14:22.568+0000] {taskinstance.py:2905} ERROR - Task failed with exception
Traceback (most recent call last):
  File "/home/airflow/.local/lib/python3.12/site-packages/airflow/models/taskinstance.py", line 465, in _execute_task
    result = _execute_callable(context=context, **execute_callable_kwargs)
             ^^^^^^^^^^^^^^^^^^^^^^^^^^^^^^^^^^^^^^^^^^^^^^^^^^^^^^^^^^^^^
  File "/home/airflow/.local/lib/python3.12/site-packages/airflow/models/taskinstance.py", line 432, in _execute_callable
    return execute_callable(context=context, **execute_callable_kwargs)
           ^^^^^^^^^^^^^^^^^^^^^^^^^^^^^^^^^^^^^^^^^^^^^^^^^^^^^^^^^^^^
  File "/home/airflow/.local/lib/python3.12/site-packages/airflow/models/baseoperator.py", line 401, in wrapper
    return func(self, *args, **kwargs)
           ^^^^^^^^^^^^^^^^^^^^^^^^^^^
  File "/home/airflow/.local/lib/python3.12/site-packages/airflow/operators/python.py", line 235, in execute
    return_value = self.execute_callable()
                   ^^^^^^^^^^^^^^^^^^^^^^^
  File "/home/airflow/.local/lib/python3.12/site-packages/airflow/operators/python.py", line 252, in execute_callable
    return self.python_callable(*self.op_args, **self.op_kwargs)
           ^^^^^^^^^^^^^^^^^^^^^^^^^^^^^^^^^^^^^^^^^^^^^^^^^^^^^
  File "/opt/airflow/dags/utils/stock_data_elt.py", line 70, in fetch_insider_transaction_data
    df = pd.DataFrame(data['data'])
                      ~~~~^^^^^^^^
KeyError: 'data'
[2024-10-28T16:14:22.585+0000] {taskinstance.py:1206} INFO - Marking task as FAILED. dag_id=fetch_and_clean_insider_transaction_data, task_id=fetch_insider_transaction_data, run_id=manual__2024-10-28T15:53:59.592313+00:00, execution_date=20241028T155359, start_date=20241028T161421, end_date=20241028T161422
[2024-10-28T16:14:22.596+0000] {standard_task_runner.py:110} ERROR - Failed to execute job 53 for task fetch_insider_transaction_data ('data'; 208)
[2024-10-28T16:14:22.630+0000] {local_task_job_runner.py:240} INFO - Task exited with return code 1
[2024-10-28T16:14:22.654+0000] {taskinstance.py:3503} INFO - 0 downstream tasks scheduled from follow-on schedule check
[2024-10-28T16:14:22.658+0000] {local_task_job_runner.py:222} INFO - ::endgroup::
