[2024-10-28T16:09:03.915+0000] {local_task_job_runner.py:120} INFO - ::group::Pre task execution logs
[2024-10-28T16:09:03.946+0000] {taskinstance.py:2076} INFO - Dependencies all met for dep_context=non-requeueable deps ti=<TaskInstance: fetch_and_clean_insider_transaction_data.fetch_insider_transaction_data manual__2024-10-28T15:53:59.592313+00:00 [queued]>
[2024-10-28T16:09:03.953+0000] {taskinstance.py:2076} INFO - Dependencies all met for dep_context=requeueable deps ti=<TaskInstance: fetch_and_clean_insider_transaction_data.fetch_insider_transaction_data manual__2024-10-28T15:53:59.592313+00:00 [queued]>
[2024-10-28T16:09:03.953+0000] {taskinstance.py:2306} INFO - Starting attempt 6 of 6
[2024-10-28T16:09:03.962+0000] {taskinstance.py:2330} INFO - Executing <Task(PythonOperator): fetch_insider_transaction_data> on 2024-10-28 15:53:59.592313+00:00
[2024-10-28T16:09:03.970+0000] {logging_mixin.py:188} WARNING - /home/***/.local/lib/python3.12/site-packages/***/task/task_runner/standard_task_runner.py:61 DeprecationWarning: This process (pid=1505) is multi-threaded, use of fork() may lead to deadlocks in the child.
[2024-10-28T16:09:03.972+0000] {standard_task_runner.py:63} INFO - Started process 1507 to run task
[2024-10-28T16:09:03.972+0000] {standard_task_runner.py:90} INFO - Running: ['***', 'tasks', 'run', 'fetch_and_clean_insider_transaction_data', 'fetch_insider_transaction_data', 'manual__2024-10-28T15:53:59.592313+00:00', '--job-id', '49', '--raw', '--subdir', 'DAGS_FOLDER/stock_data_pipelines.py', '--cfg-path', '/tmp/tmp7eg3y4ey']
[2024-10-28T16:09:03.975+0000] {standard_task_runner.py:91} INFO - Job 49: Subtask fetch_insider_transaction_data
[2024-10-28T16:09:03.994+0000] {logging_mixin.py:188} WARNING - /home/***/.local/lib/python3.12/site-packages/***/settings.py:195 DeprecationWarning: The sql_alchemy_conn option in [core] has been moved to the sql_alchemy_conn option in [database] - the old setting has been used, but please update your config.
[2024-10-28T16:09:04.039+0000] {task_command.py:426} INFO - Running <TaskInstance: fetch_and_clean_insider_transaction_data.fetch_insider_transaction_data manual__2024-10-28T15:53:59.592313+00:00 [running]> on host 66a068bd0545
[2024-10-28T16:09:04.129+0000] {taskinstance.py:2648} INFO - Exporting env vars: AIRFLOW_CTX_DAG_OWNER='***' AIRFLOW_CTX_DAG_ID='fetch_and_clean_insider_transaction_data' AIRFLOW_CTX_TASK_ID='fetch_insider_transaction_data' AIRFLOW_CTX_EXECUTION_DATE='2024-10-28T15:53:59.592313+00:00' AIRFLOW_CTX_TRY_NUMBER='6' AIRFLOW_CTX_DAG_RUN_ID='manual__2024-10-28T15:53:59.592313+00:00'
[2024-10-28T16:09:04.130+0000] {taskinstance.py:430} INFO - ::endgroup::
[2024-10-28T16:09:04.815+0000] {taskinstance.py:441} INFO - ::group::Post task execution logs
[2024-10-28T16:09:04.819+0000] {taskinstance.py:2905} ERROR - Task failed with exception
Traceback (most recent call last):
  File "/home/airflow/.local/lib/python3.12/site-packages/airflow/models/taskinstance.py", line 465, in _execute_task
    result = _execute_callable(context=context, **execute_callable_kwargs)
             ^^^^^^^^^^^^^^^^^^^^^^^^^^^^^^^^^^^^^^^^^^^^^^^^^^^^^^^^^^^^^
  File "/home/airflow/.local/lib/python3.12/site-packages/airflow/models/taskinstance.py", line 432, in _execute_callable
    return execute_callable(context=context, **execute_callable_kwargs)
           ^^^^^^^^^^^^^^^^^^^^^^^^^^^^^^^^^^^^^^^^^^^^^^^^^^^^^^^^^^^^
  File "/home/airflow/.local/lib/python3.12/site-packages/airflow/models/baseoperator.py", line 401, in wrapper
    return func(self, *args, **kwargs)
           ^^^^^^^^^^^^^^^^^^^^^^^^^^^
  File "/home/airflow/.local/lib/python3.12/site-packages/airflow/operators/python.py", line 235, in execute
    return_value = self.execute_callable()
                   ^^^^^^^^^^^^^^^^^^^^^^^
  File "/home/airflow/.local/lib/python3.12/site-packages/airflow/operators/python.py", line 252, in execute_callable
    return self.python_callable(*self.op_args, **self.op_kwargs)
           ^^^^^^^^^^^^^^^^^^^^^^^^^^^^^^^^^^^^^^^^^^^^^^^^^^^^^
  File "/opt/airflow/dags/utils/stock_data_elt.py", line 68, in fetch_insider_transaction_data
    df = pd.DataFrame(response.json())
         ^^^^^^^^^^^^^^^^^^^^^^^^^^^^^
  File "/home/airflow/.local/lib/python3.12/site-packages/pandas/core/frame.py", line 733, in __init__
    mgr = dict_to_mgr(data, index, columns, dtype=dtype, copy=copy, typ=manager)
          ^^^^^^^^^^^^^^^^^^^^^^^^^^^^^^^^^^^^^^^^^^^^^^^^^^^^^^^^^^^^^^^^^^^^^^
  File "/home/airflow/.local/lib/python3.12/site-packages/pandas/core/internals/construction.py", line 503, in dict_to_mgr
    return arrays_to_mgr(arrays, columns, index, dtype=dtype, typ=typ, consolidate=copy)
           ^^^^^^^^^^^^^^^^^^^^^^^^^^^^^^^^^^^^^^^^^^^^^^^^^^^^^^^^^^^^^^^^^^^^^^^^^^^^^
  File "/home/airflow/.local/lib/python3.12/site-packages/pandas/core/internals/construction.py", line 114, in arrays_to_mgr
    index = _extract_index(arrays)
            ^^^^^^^^^^^^^^^^^^^^^^
  File "/home/airflow/.local/lib/python3.12/site-packages/pandas/core/internals/construction.py", line 667, in _extract_index
    raise ValueError("If using all scalar values, you must pass an index")
ValueError: If using all scalar values, you must pass an index
[2024-10-28T16:09:04.857+0000] {taskinstance.py:1206} INFO - Marking task as FAILED. dag_id=fetch_and_clean_insider_transaction_data, task_id=fetch_insider_transaction_data, run_id=manual__2024-10-28T15:53:59.592313+00:00, execution_date=20241028T155359, start_date=20241028T160903, end_date=20241028T160904
[2024-10-28T16:09:04.869+0000] {standard_task_runner.py:110} ERROR - Failed to execute job 49 for task fetch_insider_transaction_data (If using all scalar values, you must pass an index; 1507)
[2024-10-28T16:09:04.918+0000] {local_task_job_runner.py:240} INFO - Task exited with return code 1
[2024-10-28T16:09:04.941+0000] {taskinstance.py:3503} INFO - 0 downstream tasks scheduled from follow-on schedule check
[2024-10-28T16:09:04.945+0000] {local_task_job_runner.py:222} INFO - ::endgroup::
