[2024-10-29T18:12:32.273+0000] {local_task_job_runner.py:120} INFO - ::group::Pre task execution logs
[2024-10-29T18:12:32.305+0000] {taskinstance.py:2076} INFO - Dependencies all met for dep_context=non-requeueable deps ti=<TaskInstance: fetch_and_clean_stock_data.clean_stock_data manual__2024-10-28T15:07:03.349825+00:00 [queued]>
[2024-10-29T18:12:32.311+0000] {taskinstance.py:2076} INFO - Dependencies all met for dep_context=requeueable deps ti=<TaskInstance: fetch_and_clean_stock_data.clean_stock_data manual__2024-10-28T15:07:03.349825+00:00 [queued]>
[2024-10-29T18:12:32.312+0000] {taskinstance.py:2306} INFO - Starting attempt 3 of 3
[2024-10-29T18:12:32.321+0000] {taskinstance.py:2330} INFO - Executing <Task(PythonOperator): clean_stock_data> on 2024-10-28 15:07:03.349825+00:00
[2024-10-29T18:12:32.333+0000] {logging_mixin.py:188} WARNING - /home/***/.local/lib/python3.12/site-packages/***/task/task_runner/standard_task_runner.py:61 DeprecationWarning: This process (pid=4631) is multi-threaded, use of fork() may lead to deadlocks in the child.
[2024-10-29T18:12:32.336+0000] {standard_task_runner.py:63} INFO - Started process 4636 to run task
[2024-10-29T18:12:32.334+0000] {standard_task_runner.py:90} INFO - Running: ['***', 'tasks', 'run', 'fetch_and_clean_stock_data', 'clean_stock_data', 'manual__2024-10-28T15:07:03.349825+00:00', '--job-id', '234', '--raw', '--subdir', 'DAGS_FOLDER/stock_data_pipelines.py', '--cfg-path', '/tmp/tmphkw28dnp']
[2024-10-29T18:12:32.338+0000] {standard_task_runner.py:91} INFO - Job 234: Subtask clean_stock_data
[2024-10-29T18:12:32.367+0000] {logging_mixin.py:188} WARNING - /home/***/.local/lib/python3.12/site-packages/***/settings.py:195 DeprecationWarning: The sql_alchemy_conn option in [core] has been moved to the sql_alchemy_conn option in [database] - the old setting has been used, but please update your config.
[2024-10-29T18:12:32.482+0000] {task_command.py:426} INFO - Running <TaskInstance: fetch_and_clean_stock_data.clean_stock_data manual__2024-10-28T15:07:03.349825+00:00 [running]> on host a5e3407ec3e4
[2024-10-29T18:12:32.658+0000] {taskinstance.py:2648} INFO - Exporting env vars: AIRFLOW_CTX_DAG_OWNER='***' AIRFLOW_CTX_DAG_ID='fetch_and_clean_stock_data' AIRFLOW_CTX_TASK_ID='clean_stock_data' AIRFLOW_CTX_EXECUTION_DATE='2024-10-28T15:07:03.349825+00:00' AIRFLOW_CTX_TRY_NUMBER='3' AIRFLOW_CTX_DAG_RUN_ID='manual__2024-10-28T15:07:03.349825+00:00'
[2024-10-29T18:12:32.663+0000] {taskinstance.py:430} INFO - ::endgroup::
[2024-10-29T18:12:32.752+0000] {taskinstance.py:441} INFO - ::group::Post task execution logs
[2024-10-29T18:12:32.754+0000] {taskinstance.py:2905} ERROR - Task failed with exception
Traceback (most recent call last):
  File "/home/airflow/.local/lib/python3.12/site-packages/pandas/core/indexes/base.py", line 3791, in get_loc
    return self._engine.get_loc(casted_key)
           ^^^^^^^^^^^^^^^^^^^^^^^^^^^^^^^^
  File "index.pyx", line 152, in pandas._libs.index.IndexEngine.get_loc
  File "index.pyx", line 181, in pandas._libs.index.IndexEngine.get_loc
  File "pandas/_libs/hashtable_class_helper.pxi", line 7080, in pandas._libs.hashtable.PyObjectHashTable.get_item
  File "pandas/_libs/hashtable_class_helper.pxi", line 7088, in pandas._libs.hashtable.PyObjectHashTable.get_item
KeyError: 'timestamp'

The above exception was the direct cause of the following exception:

Traceback (most recent call last):
  File "/home/airflow/.local/lib/python3.12/site-packages/airflow/models/taskinstance.py", line 465, in _execute_task
    result = _execute_callable(context=context, **execute_callable_kwargs)
             ^^^^^^^^^^^^^^^^^^^^^^^^^^^^^^^^^^^^^^^^^^^^^^^^^^^^^^^^^^^^^
  File "/home/airflow/.local/lib/python3.12/site-packages/airflow/models/taskinstance.py", line 432, in _execute_callable
    return execute_callable(context=context, **execute_callable_kwargs)
           ^^^^^^^^^^^^^^^^^^^^^^^^^^^^^^^^^^^^^^^^^^^^^^^^^^^^^^^^^^^^
  File "/home/airflow/.local/lib/python3.12/site-packages/airflow/models/baseoperator.py", line 401, in wrapper
    return func(self, *args, **kwargs)
           ^^^^^^^^^^^^^^^^^^^^^^^^^^^
  File "/home/airflow/.local/lib/python3.12/site-packages/airflow/operators/python.py", line 235, in execute
    return_value = self.execute_callable()
                   ^^^^^^^^^^^^^^^^^^^^^^^
  File "/home/airflow/.local/lib/python3.12/site-packages/airflow/operators/python.py", line 252, in execute_callable
    return self.python_callable(*self.op_args, **self.op_kwargs)
           ^^^^^^^^^^^^^^^^^^^^^^^^^^^^^^^^^^^^^^^^^^^^^^^^^^^^^
  File "/opt/airflow/dags/utils/stock_data_elt.py", line 42, in clean_stock_data
    df['timestamp'] = pd.to_datetime(df['timestamp'])
                                     ~~^^^^^^^^^^^^^
  File "/home/airflow/.local/lib/python3.12/site-packages/pandas/core/frame.py", line 3893, in __getitem__
    indexer = self.columns.get_loc(key)
              ^^^^^^^^^^^^^^^^^^^^^^^^^
  File "/home/airflow/.local/lib/python3.12/site-packages/pandas/core/indexes/base.py", line 3798, in get_loc
    raise KeyError(key) from err
KeyError: 'timestamp'
[2024-10-29T18:12:32.776+0000] {taskinstance.py:1206} INFO - Marking task as FAILED. dag_id=fetch_and_clean_stock_data, task_id=clean_stock_data, run_id=manual__2024-10-28T15:07:03.349825+00:00, execution_date=20241028T150703, start_date=20241029T181232, end_date=20241029T181232
[2024-10-29T18:12:32.820+0000] {standard_task_runner.py:110} ERROR - Failed to execute job 234 for task clean_stock_data ('timestamp'; 4636)
[2024-10-29T18:12:32.887+0000] {local_task_job_runner.py:240} INFO - Task exited with return code 1
[2024-10-29T18:12:32.915+0000] {taskinstance.py:3503} INFO - 0 downstream tasks scheduled from follow-on schedule check
[2024-10-29T18:12:32.921+0000] {local_task_job_runner.py:222} INFO - ::endgroup::
