[2024-10-28T13:12:18.098+0000] {local_task_job_runner.py:120} INFO - ::group::Pre task execution logs
[2024-10-28T13:12:18.118+0000] {taskinstance.py:2076} INFO - Dependencies all met for dep_context=non-requeueable deps ti=<TaskInstance: fetch_and_preprocess_stock_data.store_data_in_s3 manual__2024-10-28T13:06:16.622464+00:00 [queued]>
[2024-10-28T13:12:18.122+0000] {taskinstance.py:2076} INFO - Dependencies all met for dep_context=requeueable deps ti=<TaskInstance: fetch_and_preprocess_stock_data.store_data_in_s3 manual__2024-10-28T13:06:16.622464+00:00 [queued]>
[2024-10-28T13:12:18.122+0000] {taskinstance.py:2306} INFO - Starting attempt 1 of 1
[2024-10-28T13:12:18.128+0000] {taskinstance.py:2330} INFO - Executing <Task(PythonOperator): store_data_in_s3> on 2024-10-28 13:06:16.622464+00:00
[2024-10-28T13:12:18.134+0000] {logging_mixin.py:188} WARNING - /home/***/.local/lib/python3.12/site-packages/***/task/task_runner/standard_task_runner.py:61 DeprecationWarning: This process (pid=211) is multi-threaded, use of fork() may lead to deadlocks in the child.
[2024-10-28T13:12:18.135+0000] {standard_task_runner.py:63} INFO - Started process 213 to run task
[2024-10-28T13:12:18.135+0000] {standard_task_runner.py:90} INFO - Running: ['***', 'tasks', 'run', 'fetch_and_preprocess_stock_data', 'store_data_in_s3', 'manual__2024-10-28T13:06:16.622464+00:00', '--job-id', '5', '--raw', '--subdir', 'DAGS_FOLDER/stock_data_pipelines.py', '--cfg-path', '/tmp/tmpd7923hhr']
[2024-10-28T13:12:18.137+0000] {standard_task_runner.py:91} INFO - Job 5: Subtask store_data_in_s3
[2024-10-28T13:12:18.150+0000] {logging_mixin.py:188} WARNING - /home/***/.local/lib/python3.12/site-packages/***/settings.py:195 DeprecationWarning: The sql_alchemy_conn option in [core] has been moved to the sql_alchemy_conn option in [database] - the old setting has been used, but please update your config.
[2024-10-28T13:12:18.178+0000] {task_command.py:426} INFO - Running <TaskInstance: fetch_and_preprocess_stock_data.store_data_in_s3 manual__2024-10-28T13:06:16.622464+00:00 [running]> on host 9c1e41f547e2
[2024-10-28T13:12:18.236+0000] {taskinstance.py:2648} INFO - Exporting env vars: AIRFLOW_CTX_DAG_OWNER='***' AIRFLOW_CTX_DAG_ID='fetch_and_preprocess_stock_data' AIRFLOW_CTX_TASK_ID='store_data_in_s3' AIRFLOW_CTX_EXECUTION_DATE='2024-10-28T13:06:16.622464+00:00' AIRFLOW_CTX_TRY_NUMBER='1' AIRFLOW_CTX_DAG_RUN_ID='manual__2024-10-28T13:06:16.622464+00:00'
[2024-10-28T13:12:18.237+0000] {taskinstance.py:430} INFO - ::endgroup::
[2024-10-28T13:12:18.244+0000] {taskinstance.py:441} INFO - ::group::Post task execution logs
[2024-10-28T13:12:18.245+0000] {taskinstance.py:2905} ERROR - Task failed with exception
Traceback (most recent call last):
  File "/home/airflow/.local/lib/python3.12/site-packages/airflow/models/taskinstance.py", line 465, in _execute_task
    result = _execute_callable(context=context, **execute_callable_kwargs)
             ^^^^^^^^^^^^^^^^^^^^^^^^^^^^^^^^^^^^^^^^^^^^^^^^^^^^^^^^^^^^^
  File "/home/airflow/.local/lib/python3.12/site-packages/airflow/models/taskinstance.py", line 432, in _execute_callable
    return execute_callable(context=context, **execute_callable_kwargs)
           ^^^^^^^^^^^^^^^^^^^^^^^^^^^^^^^^^^^^^^^^^^^^^^^^^^^^^^^^^^^^
  File "/home/airflow/.local/lib/python3.12/site-packages/airflow/models/baseoperator.py", line 401, in wrapper
    return func(self, *args, **kwargs)
           ^^^^^^^^^^^^^^^^^^^^^^^^^^^
  File "/home/airflow/.local/lib/python3.12/site-packages/airflow/operators/python.py", line 233, in execute
    self.op_kwargs = self.determine_kwargs(context)
                     ^^^^^^^^^^^^^^^^^^^^^^^^^^^^^^
  File "/home/airflow/.local/lib/python3.12/site-packages/airflow/operators/python.py", line 244, in determine_kwargs
    return KeywordParameters.determine(self.python_callable, self.op_args, context).unpacking()
           ^^^^^^^^^^^^^^^^^^^^^^^^^^^^^^^^^^^^^^^^^^^^^^^^^^^^^^^^^^^^^^^^^^^^^^^^
  File "/home/airflow/.local/lib/python3.12/site-packages/airflow/utils/operator_helpers.py", line 163, in determine
    raise ValueError(f"The key {name!r} in args is a part of kwargs and therefore reserved.")
ValueError: The key 'ti' in args is a part of kwargs and therefore reserved.
[2024-10-28T13:12:18.254+0000] {taskinstance.py:1206} INFO - Marking task as FAILED. dag_id=fetch_and_preprocess_stock_data, task_id=store_data_in_s3, run_id=manual__2024-10-28T13:06:16.622464+00:00, execution_date=20241028T130616, start_date=20241028T131218, end_date=20241028T131218
[2024-10-28T13:12:18.260+0000] {standard_task_runner.py:110} ERROR - Failed to execute job 5 for task store_data_in_s3 (The key 'ti' in args is a part of kwargs and therefore reserved.; 213)
[2024-10-28T13:12:18.314+0000] {local_task_job_runner.py:240} INFO - Task exited with return code 1
[2024-10-28T13:12:18.328+0000] {taskinstance.py:3503} INFO - 0 downstream tasks scheduled from follow-on schedule check
[2024-10-28T13:12:18.330+0000] {local_task_job_runner.py:222} INFO - ::endgroup::
