[2024-10-30T15:45:54.878+0000] {local_task_job_runner.py:120} INFO - ::group::Pre task execution logs
[2024-10-30T15:45:54.915+0000] {taskinstance.py:2076} INFO - Dependencies all met for dep_context=non-requeueable deps ti=<TaskInstance: Predice-Stock-ML-Pipeline.run_ml_workload manual__2024-10-30T14:27:23.134497+00:00 [queued]>
[2024-10-30T15:45:54.935+0000] {taskinstance.py:2076} INFO - Dependencies all met for dep_context=requeueable deps ti=<TaskInstance: Predice-Stock-ML-Pipeline.run_ml_workload manual__2024-10-30T14:27:23.134497+00:00 [queued]>
[2024-10-30T15:45:54.936+0000] {taskinstance.py:2306} INFO - Starting attempt 15 of 15
[2024-10-30T15:45:54.945+0000] {taskinstance.py:2330} INFO - Executing <Task(PythonOperator): run_ml_workload> on 2024-10-30 14:27:23.134497+00:00
[2024-10-30T15:45:54.957+0000] {logging_mixin.py:188} WARNING - /home/***/.local/lib/python3.12/site-packages/***/task/task_runner/standard_task_runner.py:61 DeprecationWarning: This process (pid=7581) is multi-threaded, use of fork() may lead to deadlocks in the child.
[2024-10-30T15:45:54.959+0000] {standard_task_runner.py:63} INFO - Started process 7597 to run task
[2024-10-30T15:45:54.958+0000] {standard_task_runner.py:90} INFO - Running: ['***', 'tasks', 'run', 'Predice-Stock-ML-Pipeline', 'run_ml_workload', 'manual__2024-10-30T14:27:23.134497+00:00', '--job-id', '342', '--raw', '--subdir', 'DAGS_FOLDER/stock_and_sentiment_ml_pipeline.py', '--cfg-path', '/tmp/tmpvabthtzw']
[2024-10-30T15:45:54.961+0000] {standard_task_runner.py:91} INFO - Job 342: Subtask run_ml_workload
[2024-10-30T15:45:54.981+0000] {logging_mixin.py:188} WARNING - /home/***/.local/lib/python3.12/site-packages/***/settings.py:195 DeprecationWarning: The sql_alchemy_conn option in [core] has been moved to the sql_alchemy_conn option in [database] - the old setting has been used, but please update your config.
[2024-10-30T15:45:55.032+0000] {task_command.py:426} INFO - Running <TaskInstance: Predice-Stock-ML-Pipeline.run_ml_workload manual__2024-10-30T14:27:23.134497+00:00 [running]> on host cf1c99cdc1a8
[2024-10-30T15:45:55.331+0000] {taskinstance.py:2648} INFO - Exporting env vars: AIRFLOW_CTX_DAG_OWNER='***' AIRFLOW_CTX_DAG_ID='Predice-Stock-ML-Pipeline' AIRFLOW_CTX_TASK_ID='run_ml_workload' AIRFLOW_CTX_EXECUTION_DATE='2024-10-30T14:27:23.134497+00:00' AIRFLOW_CTX_TRY_NUMBER='15' AIRFLOW_CTX_DAG_RUN_ID='manual__2024-10-30T14:27:23.134497+00:00'
[2024-10-30T15:45:55.332+0000] {taskinstance.py:430} INFO - ::endgroup::
[2024-10-30T15:46:06.561+0000] {logging_mixin.py:188} INFO - Mean Squared Error for Random Forest Regression: 3.4913262575604404e-06
[2024-10-30T15:46:06.563+0000] {logging_mixin.py:188} INFO - Mean Squared Error for HistGradientBoostingRegressor: 9.76420857129024e-06
[2024-10-30T15:46:06.566+0000] {taskinstance.py:441} INFO - ::group::Post task execution logs
[2024-10-30T15:46:06.570+0000] {taskinstance.py:2905} ERROR - Task failed with exception
Traceback (most recent call last):
  File "/home/airflow/.local/lib/python3.12/site-packages/airflow/models/taskinstance.py", line 465, in _execute_task
    result = _execute_callable(context=context, **execute_callable_kwargs)
             ^^^^^^^^^^^^^^^^^^^^^^^^^^^^^^^^^^^^^^^^^^^^^^^^^^^^^^^^^^^^^
  File "/home/airflow/.local/lib/python3.12/site-packages/airflow/models/taskinstance.py", line 432, in _execute_callable
    return execute_callable(context=context, **execute_callable_kwargs)
           ^^^^^^^^^^^^^^^^^^^^^^^^^^^^^^^^^^^^^^^^^^^^^^^^^^^^^^^^^^^^
  File "/home/airflow/.local/lib/python3.12/site-packages/airflow/models/baseoperator.py", line 401, in wrapper
    return func(self, *args, **kwargs)
           ^^^^^^^^^^^^^^^^^^^^^^^^^^^
  File "/home/airflow/.local/lib/python3.12/site-packages/airflow/operators/python.py", line 235, in execute
    return_value = self.execute_callable()
                   ^^^^^^^^^^^^^^^^^^^^^^^
  File "/home/airflow/.local/lib/python3.12/site-packages/airflow/operators/python.py", line 252, in execute_callable
    return self.python_callable(*self.op_args, **self.op_kwargs)
           ^^^^^^^^^^^^^^^^^^^^^^^^^^^^^^^^^^^^^^^^^^^^^^^^^^^^^
  File "/opt/airflow/dags/utils/ml_pipeline_helper.py", line 78, in run_ml
    model_lr, model_rf = train_model(merged_data)
                         ^^^^^^^^^^^^^^^^^^^^^^^^
  File "/opt/airflow/dags/utils/ml_pipeline_helper.py", line 62, in train_model
    with open('/opt/airflow/data/gold/models/random_forest_model.pkl', 'wb') as f:
         ^^^^^^^^^^^^^^^^^^^^^^^^^^^^^^^^^^^^^^^^^^^^^^^^^^^^^^^^^^^^^^^^^^^
FileNotFoundError: [Errno 2] No such file or directory: '/opt/airflow/data/gold/models/random_forest_model.pkl'
[2024-10-30T15:46:06.589+0000] {taskinstance.py:1206} INFO - Marking task as FAILED. dag_id=Predice-Stock-ML-Pipeline, task_id=run_ml_workload, run_id=manual__2024-10-30T14:27:23.134497+00:00, execution_date=20241030T142723, start_date=20241030T154554, end_date=20241030T154606
[2024-10-30T15:46:06.607+0000] {standard_task_runner.py:110} ERROR - Failed to execute job 342 for task run_ml_workload ([Errno 2] No such file or directory: '/opt/airflow/data/gold/models/random_forest_model.pkl'; 7597)
[2024-10-30T15:46:06.735+0000] {local_task_job_runner.py:240} INFO - Task exited with return code 1
[2024-10-30T15:46:06.781+0000] {taskinstance.py:3503} INFO - 0 downstream tasks scheduled from follow-on schedule check
[2024-10-30T15:46:06.786+0000] {local_task_job_runner.py:222} INFO - ::endgroup::
