[2024-10-28T13:06:18.309+0000] {local_task_job_runner.py:120} INFO - ::group::Pre task execution logs
[2024-10-28T13:06:18.335+0000] {taskinstance.py:2076} INFO - Dependencies all met for dep_context=non-requeueable deps ti=<TaskInstance: fetch_and_preprocess_stock_data.fetch_stock_data manual__2024-10-28T13:06:16.622464+00:00 [queued]>
[2024-10-28T13:06:18.340+0000] {taskinstance.py:2076} INFO - Dependencies all met for dep_context=requeueable deps ti=<TaskInstance: fetch_and_preprocess_stock_data.fetch_stock_data manual__2024-10-28T13:06:16.622464+00:00 [queued]>
[2024-10-28T13:06:18.341+0000] {taskinstance.py:2306} INFO - Starting attempt 1 of 1
[2024-10-28T13:06:18.348+0000] {taskinstance.py:2330} INFO - Executing <Task(PythonOperator): fetch_stock_data> on 2024-10-28 13:06:16.622464+00:00
[2024-10-28T13:06:18.355+0000] {logging_mixin.py:188} WARNING - /home/***/.local/lib/python3.12/site-packages/***/task/task_runner/standard_task_runner.py:61 DeprecationWarning: This process (pid=903) is multi-threaded, use of fork() may lead to deadlocks in the child.
[2024-10-28T13:06:18.357+0000] {standard_task_runner.py:63} INFO - Started process 920 to run task
[2024-10-28T13:06:18.356+0000] {standard_task_runner.py:90} INFO - Running: ['***', 'tasks', 'run', 'fetch_and_preprocess_stock_data', 'fetch_stock_data', 'manual__2024-10-28T13:06:16.622464+00:00', '--job-id', '2', '--raw', '--subdir', 'DAGS_FOLDER/stock_data_pipelines.py', '--cfg-path', '/tmp/tmpfo53ndiw']
[2024-10-28T13:06:18.359+0000] {standard_task_runner.py:91} INFO - Job 2: Subtask fetch_stock_data
[2024-10-28T13:06:18.374+0000] {logging_mixin.py:188} WARNING - /home/***/.local/lib/python3.12/site-packages/***/settings.py:195 DeprecationWarning: The sql_alchemy_conn option in [core] has been moved to the sql_alchemy_conn option in [database] - the old setting has been used, but please update your config.
[2024-10-28T13:06:18.404+0000] {task_command.py:426} INFO - Running <TaskInstance: fetch_and_preprocess_stock_data.fetch_stock_data manual__2024-10-28T13:06:16.622464+00:00 [running]> on host 9c1e41f547e2
[2024-10-28T13:06:18.467+0000] {taskinstance.py:2648} INFO - Exporting env vars: AIRFLOW_CTX_DAG_OWNER='***' AIRFLOW_CTX_DAG_ID='fetch_and_preprocess_stock_data' AIRFLOW_CTX_TASK_ID='fetch_stock_data' AIRFLOW_CTX_EXECUTION_DATE='2024-10-28T13:06:16.622464+00:00' AIRFLOW_CTX_TRY_NUMBER='1' AIRFLOW_CTX_DAG_RUN_ID='manual__2024-10-28T13:06:16.622464+00:00'
[2024-10-28T13:06:18.468+0000] {taskinstance.py:430} INFO - ::endgroup::
[2024-10-28T13:06:25.266+0000] {taskinstance.py:441} INFO - ::group::Post task execution logs
[2024-10-28T13:06:25.269+0000] {taskinstance.py:2905} ERROR - Task failed with exception
Traceback (most recent call last):
  File "/home/airflow/.local/lib/python3.12/site-packages/requests/models.py", line 960, in json
    return complexjson.loads(self.content.decode(encoding), **kwargs)
           ^^^^^^^^^^^^^^^^^^^^^^^^^^^^^^^^^^^^^^^^^^^^^^^^^^^^^^^^^^
  File "/usr/local/lib/python3.12/json/__init__.py", line 346, in loads
    return _default_decoder.decode(s)
           ^^^^^^^^^^^^^^^^^^^^^^^^^^
  File "/usr/local/lib/python3.12/json/decoder.py", line 337, in decode
    obj, end = self.raw_decode(s, idx=_w(s, 0).end())
               ^^^^^^^^^^^^^^^^^^^^^^^^^^^^^^^^^^^^^^
  File "/usr/local/lib/python3.12/json/decoder.py", line 355, in raw_decode
    raise JSONDecodeError("Expecting value", s, err.value) from None
json.decoder.JSONDecodeError: Expecting value: line 1 column 1 (char 0)

During handling of the above exception, another exception occurred:

Traceback (most recent call last):
  File "/home/airflow/.local/lib/python3.12/site-packages/airflow/models/taskinstance.py", line 465, in _execute_task
    result = _execute_callable(context=context, **execute_callable_kwargs)
             ^^^^^^^^^^^^^^^^^^^^^^^^^^^^^^^^^^^^^^^^^^^^^^^^^^^^^^^^^^^^^
  File "/home/airflow/.local/lib/python3.12/site-packages/airflow/models/taskinstance.py", line 432, in _execute_callable
    return execute_callable(context=context, **execute_callable_kwargs)
           ^^^^^^^^^^^^^^^^^^^^^^^^^^^^^^^^^^^^^^^^^^^^^^^^^^^^^^^^^^^^
  File "/home/airflow/.local/lib/python3.12/site-packages/airflow/models/baseoperator.py", line 401, in wrapper
    return func(self, *args, **kwargs)
           ^^^^^^^^^^^^^^^^^^^^^^^^^^^
  File "/home/airflow/.local/lib/python3.12/site-packages/airflow/operators/python.py", line 235, in execute
    return_value = self.execute_callable()
                   ^^^^^^^^^^^^^^^^^^^^^^^
  File "/home/airflow/.local/lib/python3.12/site-packages/airflow/operators/python.py", line 252, in execute_callable
    return self.python_callable(*self.op_args, **self.op_kwargs)
           ^^^^^^^^^^^^^^^^^^^^^^^^^^^^^^^^^^^^^^^^^^^^^^^^^^^^^
  File "/opt/airflow/dags/utils/stock_data_elt.py", line 8, in fetch_stock_data
    data = response.json()
           ^^^^^^^^^^^^^^^
  File "/home/airflow/.local/lib/python3.12/site-packages/requests/models.py", line 968, in json
    raise RequestsJSONDecodeError(e.msg, e.doc, e.pos)
requests.exceptions.JSONDecodeError: Expecting value: line 1 column 1 (char 0)
[2024-10-28T13:06:25.305+0000] {taskinstance.py:1206} INFO - Marking task as FAILED. dag_id=fetch_and_preprocess_stock_data, task_id=fetch_stock_data, run_id=manual__2024-10-28T13:06:16.622464+00:00, execution_date=20241028T130616, start_date=20241028T130618, end_date=20241028T130625
[2024-10-28T13:06:25.319+0000] {standard_task_runner.py:110} ERROR - Failed to execute job 2 for task fetch_stock_data (Expecting value: line 1 column 1 (char 0); 920)
[2024-10-28T13:06:25.339+0000] {local_task_job_runner.py:240} INFO - Task exited with return code 1
[2024-10-28T13:06:25.355+0000] {taskinstance.py:3503} INFO - 0 downstream tasks scheduled from follow-on schedule check
[2024-10-28T13:06:25.358+0000] {local_task_job_runner.py:222} INFO - ::endgroup::
