[2024-10-29T15:09:32.831+0000] {local_task_job_runner.py:120} INFO - ::group::Pre task execution logs
[2024-10-29T15:09:32.882+0000] {taskinstance.py:2076} INFO - Dependencies all met for dep_context=non-requeueable deps ti=<TaskInstance: join_and_feature_engineer_all_data.get_technical_indicators_s3 manual__2024-10-29T14:30:15.385142+00:00 [queued]>
[2024-10-29T15:09:32.894+0000] {taskinstance.py:2076} INFO - Dependencies all met for dep_context=requeueable deps ti=<TaskInstance: join_and_feature_engineer_all_data.get_technical_indicators_s3 manual__2024-10-29T14:30:15.385142+00:00 [queued]>
[2024-10-29T15:09:32.895+0000] {taskinstance.py:2306} INFO - Starting attempt 8 of 8
[2024-10-29T15:09:32.917+0000] {taskinstance.py:2330} INFO - Executing <Task(PythonOperator): get_technical_indicators_s3> on 2024-10-29 14:30:15.385142+00:00
[2024-10-29T15:09:32.936+0000] {logging_mixin.py:188} WARNING - /home/***/.local/lib/python3.12/site-packages/***/task/task_runner/standard_task_runner.py:61 DeprecationWarning: This process (pid=3036) is multi-threaded, use of fork() may lead to deadlocks in the child.
[2024-10-29T15:09:32.939+0000] {standard_task_runner.py:63} INFO - Started process 3051 to run task
[2024-10-29T15:09:32.949+0000] {standard_task_runner.py:90} INFO - Running: ['***', 'tasks', 'run', 'join_and_feature_engineer_all_data', 'get_technical_indicators_s3', 'manual__2024-10-29T14:30:15.385142+00:00', '--job-id', '134', '--raw', '--subdir', 'DAGS_FOLDER/stock_data_pipelines.py', '--cfg-path', '/tmp/tmpuwhn5woi']
[2024-10-29T15:09:32.959+0000] {standard_task_runner.py:91} INFO - Job 134: Subtask get_technical_indicators_s3
[2024-10-29T15:09:32.997+0000] {logging_mixin.py:188} WARNING - /home/***/.local/lib/python3.12/site-packages/***/settings.py:195 DeprecationWarning: The sql_alchemy_conn option in [core] has been moved to the sql_alchemy_conn option in [database] - the old setting has been used, but please update your config.
[2024-10-29T15:09:33.096+0000] {task_command.py:426} INFO - Running <TaskInstance: join_and_feature_engineer_all_data.get_technical_indicators_s3 manual__2024-10-29T14:30:15.385142+00:00 [running]> on host c64098c5955c
[2024-10-29T15:09:33.249+0000] {taskinstance.py:2648} INFO - Exporting env vars: AIRFLOW_CTX_DAG_OWNER='***' AIRFLOW_CTX_DAG_ID='join_and_feature_engineer_all_data' AIRFLOW_CTX_TASK_ID='get_technical_indicators_s3' AIRFLOW_CTX_EXECUTION_DATE='2024-10-29T14:30:15.385142+00:00' AIRFLOW_CTX_TRY_NUMBER='8' AIRFLOW_CTX_DAG_RUN_ID='manual__2024-10-29T14:30:15.385142+00:00'
[2024-10-29T15:09:33.252+0000] {taskinstance.py:430} INFO - ::endgroup::
[2024-10-29T15:09:33.298+0000] {credentials.py:1147} INFO - Found credentials in environment variables.
[2024-10-29T15:09:34.401+0000] {logging_mixin.py:188} INFO - 403
[2024-10-29T15:09:34.403+0000] {logging_mixin.py:188} INFO - Forbidden
[2024-10-29T15:09:34.404+0000] {taskinstance.py:441} INFO - ::group::Post task execution logs
[2024-10-29T15:09:34.405+0000] {taskinstance.py:2905} ERROR - Task failed with exception
Traceback (most recent call last):
  File "/home/airflow/.local/lib/python3.12/site-packages/airflow/models/taskinstance.py", line 465, in _execute_task
    result = _execute_callable(context=context, **execute_callable_kwargs)
             ^^^^^^^^^^^^^^^^^^^^^^^^^^^^^^^^^^^^^^^^^^^^^^^^^^^^^^^^^^^^^
  File "/home/airflow/.local/lib/python3.12/site-packages/airflow/models/taskinstance.py", line 432, in _execute_callable
    return execute_callable(context=context, **execute_callable_kwargs)
           ^^^^^^^^^^^^^^^^^^^^^^^^^^^^^^^^^^^^^^^^^^^^^^^^^^^^^^^^^^^^
  File "/home/airflow/.local/lib/python3.12/site-packages/airflow/models/baseoperator.py", line 401, in wrapper
    return func(self, *args, **kwargs)
           ^^^^^^^^^^^^^^^^^^^^^^^^^^^
  File "/home/airflow/.local/lib/python3.12/site-packages/airflow/operators/python.py", line 235, in execute
    return_value = self.execute_callable()
                   ^^^^^^^^^^^^^^^^^^^^^^^
  File "/home/airflow/.local/lib/python3.12/site-packages/airflow/operators/python.py", line 252, in execute_callable
    return self.python_callable(*self.op_args, **self.op_kwargs)
           ^^^^^^^^^^^^^^^^^^^^^^^^^^^^^^^^^^^^^^^^^^^^^^^^^^^^^
  File "/opt/airflow/dags/utils/s3_helper.py", line 75, in get_technical_indicators_data_from_s3
    return get_from_s3(bronze_technical_indicators_data_file_name)
           ^^^^^^^^^^^^^^^^^^^^^^^^^^^^^^^^^^^^^^^^^^^^^^^^^^^^^^^
  File "/opt/airflow/dags/utils/s3_helper.py", line 45, in get_from_s3
    raise error
  File "/opt/airflow/dags/utils/s3_helper.py", line 39, in get_from_s3
    s3.download_file(bucket_name, file_name, local_path)
  File "/home/airflow/.local/lib/python3.12/site-packages/boto3/s3/inject.py", line 192, in download_file
    return transfer.download_file(
           ^^^^^^^^^^^^^^^^^^^^^^^
  File "/home/airflow/.local/lib/python3.12/site-packages/boto3/s3/transfer.py", line 405, in download_file
    future.result()
  File "/home/airflow/.local/lib/python3.12/site-packages/s3transfer/futures.py", line 103, in result
    return self._coordinator.result()
           ^^^^^^^^^^^^^^^^^^^^^^^^^^
  File "/home/airflow/.local/lib/python3.12/site-packages/s3transfer/futures.py", line 266, in result
    raise self._exception
  File "/home/airflow/.local/lib/python3.12/site-packages/s3transfer/tasks.py", line 269, in _main
    self._submit(transfer_future=transfer_future, **kwargs)
  File "/home/airflow/.local/lib/python3.12/site-packages/s3transfer/download.py", line 354, in _submit
    response = client.head_object(
               ^^^^^^^^^^^^^^^^^^^
  File "/home/airflow/.local/lib/python3.12/site-packages/botocore/client.py", line 565, in _api_call
    return self._make_api_call(operation_name, kwargs)
           ^^^^^^^^^^^^^^^^^^^^^^^^^^^^^^^^^^^^^^^^^^^
  File "/home/airflow/.local/lib/python3.12/site-packages/botocore/client.py", line 1021, in _make_api_call
    raise error_class(parsed_response, operation_name)
botocore.exceptions.ClientError: An error occurred (403) when calling the HeadObject operation: Forbidden
[2024-10-29T15:09:34.428+0000] {taskinstance.py:1206} INFO - Marking task as FAILED. dag_id=join_and_feature_engineer_all_data, task_id=get_technical_indicators_s3, run_id=manual__2024-10-29T14:30:15.385142+00:00, execution_date=20241029T143015, start_date=20241029T150932, end_date=20241029T150934
[2024-10-29T15:09:34.446+0000] {standard_task_runner.py:110} ERROR - Failed to execute job 134 for task get_technical_indicators_s3 (An error occurred (403) when calling the HeadObject operation: Forbidden; 3051)
[2024-10-29T15:09:34.510+0000] {local_task_job_runner.py:240} INFO - Task exited with return code 1
[2024-10-29T15:09:34.536+0000] {local_task_job_runner.py:222} INFO - ::endgroup::
