[2024-10-28T15:56:25.165+0000] {local_task_job_runner.py:120} INFO - ::group::Pre task execution logs
[2024-10-28T15:56:25.198+0000] {taskinstance.py:2076} INFO - Dependencies all met for dep_context=non-requeueable deps ti=<TaskInstance: fetch_and_clean_insider_transaction_data.clean_insider_transaction_data manual__2024-10-28T15:53:59.592313+00:00 [queued]>
[2024-10-28T15:56:25.206+0000] {taskinstance.py:2076} INFO - Dependencies all met for dep_context=requeueable deps ti=<TaskInstance: fetch_and_clean_insider_transaction_data.clean_insider_transaction_data manual__2024-10-28T15:53:59.592313+00:00 [queued]>
[2024-10-28T15:56:25.207+0000] {taskinstance.py:2306} INFO - Starting attempt 2 of 2
[2024-10-28T15:56:25.216+0000] {taskinstance.py:2330} INFO - Executing <Task(PythonOperator): clean_insider_transaction_data> on 2024-10-28 15:53:59.592313+00:00
[2024-10-28T15:56:25.224+0000] {logging_mixin.py:188} WARNING - /home/***/.local/lib/python3.12/site-packages/***/task/task_runner/standard_task_runner.py:61 DeprecationWarning: This process (pid=688) is multi-threaded, use of fork() may lead to deadlocks in the child.
[2024-10-28T15:56:25.227+0000] {standard_task_runner.py:63} INFO - Started process 690 to run task
[2024-10-28T15:56:25.226+0000] {standard_task_runner.py:90} INFO - Running: ['***', 'tasks', 'run', 'fetch_and_clean_insider_transaction_data', 'clean_insider_transaction_data', 'manual__2024-10-28T15:53:59.592313+00:00', '--job-id', '42', '--raw', '--subdir', 'DAGS_FOLDER/stock_data_pipelines.py', '--cfg-path', '/tmp/tmp5qzcm_vs']
[2024-10-28T15:56:25.230+0000] {standard_task_runner.py:91} INFO - Job 42: Subtask clean_insider_transaction_data
[2024-10-28T15:56:25.250+0000] {logging_mixin.py:188} WARNING - /home/***/.local/lib/python3.12/site-packages/***/settings.py:195 DeprecationWarning: The sql_alchemy_conn option in [core] has been moved to the sql_alchemy_conn option in [database] - the old setting has been used, but please update your config.
[2024-10-28T15:56:25.297+0000] {task_command.py:426} INFO - Running <TaskInstance: fetch_and_clean_insider_transaction_data.clean_insider_transaction_data manual__2024-10-28T15:53:59.592313+00:00 [running]> on host 66a068bd0545
[2024-10-28T15:56:25.393+0000] {taskinstance.py:2648} INFO - Exporting env vars: AIRFLOW_CTX_DAG_OWNER='***' AIRFLOW_CTX_DAG_ID='fetch_and_clean_insider_transaction_data' AIRFLOW_CTX_TASK_ID='clean_insider_transaction_data' AIRFLOW_CTX_EXECUTION_DATE='2024-10-28T15:53:59.592313+00:00' AIRFLOW_CTX_TRY_NUMBER='2' AIRFLOW_CTX_DAG_RUN_ID='manual__2024-10-28T15:53:59.592313+00:00'
[2024-10-28T15:56:25.403+0000] {taskinstance.py:430} INFO - ::endgroup::
[2024-10-28T15:56:25.628+0000] {taskinstance.py:441} INFO - ::group::Post task execution logs
[2024-10-28T15:56:25.630+0000] {taskinstance.py:2905} ERROR - Task failed with exception
Traceback (most recent call last):
  File "/home/airflow/.local/lib/python3.12/site-packages/pandas/core/indexes/base.py", line 3791, in get_loc
    return self._engine.get_loc(casted_key)
           ^^^^^^^^^^^^^^^^^^^^^^^^^^^^^^^^
  File "index.pyx", line 152, in pandas._libs.index.IndexEngine.get_loc
  File "index.pyx", line 181, in pandas._libs.index.IndexEngine.get_loc
  File "pandas/_libs/hashtable_class_helper.pxi", line 7080, in pandas._libs.hashtable.PyObjectHashTable.get_item
  File "pandas/_libs/hashtable_class_helper.pxi", line 7088, in pandas._libs.hashtable.PyObjectHashTable.get_item
KeyError: 'shares1'

The above exception was the direct cause of the following exception:

Traceback (most recent call last):
  File "/home/airflow/.local/lib/python3.12/site-packages/airflow/models/taskinstance.py", line 465, in _execute_task
    result = _execute_callable(context=context, **execute_callable_kwargs)
             ^^^^^^^^^^^^^^^^^^^^^^^^^^^^^^^^^^^^^^^^^^^^^^^^^^^^^^^^^^^^^
  File "/home/airflow/.local/lib/python3.12/site-packages/airflow/models/taskinstance.py", line 432, in _execute_callable
    return execute_callable(context=context, **execute_callable_kwargs)
           ^^^^^^^^^^^^^^^^^^^^^^^^^^^^^^^^^^^^^^^^^^^^^^^^^^^^^^^^^^^^
  File "/home/airflow/.local/lib/python3.12/site-packages/airflow/models/baseoperator.py", line 401, in wrapper
    return func(self, *args, **kwargs)
           ^^^^^^^^^^^^^^^^^^^^^^^^^^^
  File "/home/airflow/.local/lib/python3.12/site-packages/airflow/operators/python.py", line 235, in execute
    return_value = self.execute_callable()
                   ^^^^^^^^^^^^^^^^^^^^^^^
  File "/home/airflow/.local/lib/python3.12/site-packages/airflow/operators/python.py", line 252, in execute_callable
    return self.python_callable(*self.op_args, **self.op_kwargs)
           ^^^^^^^^^^^^^^^^^^^^^^^^^^^^^^^^^^^^^^^^^^^^^^^^^^^^^
  File "/opt/airflow/dags/utils/stock_data_elt.py", line 90, in clean_insider_transaction_data
    df[col] = pd.to_numeric(df[col], errors='coerce')
                            ~~^^^^^
  File "/home/airflow/.local/lib/python3.12/site-packages/pandas/core/frame.py", line 3893, in __getitem__
    indexer = self.columns.get_loc(key)
              ^^^^^^^^^^^^^^^^^^^^^^^^^
  File "/home/airflow/.local/lib/python3.12/site-packages/pandas/core/indexes/base.py", line 3798, in get_loc
    raise KeyError(key) from err
KeyError: 'shares1'
[2024-10-28T15:56:25.670+0000] {taskinstance.py:1206} INFO - Marking task as FAILED. dag_id=fetch_and_clean_insider_transaction_data, task_id=clean_insider_transaction_data, run_id=manual__2024-10-28T15:53:59.592313+00:00, execution_date=20241028T155359, start_date=20241028T155625, end_date=20241028T155625
[2024-10-28T15:56:25.683+0000] {standard_task_runner.py:110} ERROR - Failed to execute job 42 for task clean_insider_transaction_data ('shares1'; 690)
[2024-10-28T15:56:25.772+0000] {local_task_job_runner.py:240} INFO - Task exited with return code 1
[2024-10-28T15:56:25.811+0000] {taskinstance.py:3503} INFO - 0 downstream tasks scheduled from follow-on schedule check
[2024-10-28T15:56:25.816+0000] {local_task_job_runner.py:222} INFO - ::endgroup::
