[2024-10-30T00:34:08.116+0000] {local_task_job_runner.py:120} INFO - ::group::Pre task execution logs
[2024-10-30T00:34:08.174+0000] {taskinstance.py:2076} INFO - Dependencies all met for dep_context=non-requeueable deps ti=<TaskInstance: Stock-Data-Pipeline.clean_stock_data manual__2024-10-30T00:33:57.081828+00:00 [queued]>
[2024-10-30T00:34:08.192+0000] {taskinstance.py:2076} INFO - Dependencies all met for dep_context=requeueable deps ti=<TaskInstance: Stock-Data-Pipeline.clean_stock_data manual__2024-10-30T00:33:57.081828+00:00 [queued]>
[2024-10-30T00:34:08.193+0000] {taskinstance.py:2306} INFO - Starting attempt 1 of 1
[2024-10-30T00:34:08.218+0000] {taskinstance.py:2330} INFO - Executing <Task(PythonOperator): clean_stock_data> on 2024-10-30 00:33:57.081828+00:00
[2024-10-30T00:34:08.258+0000] {logging_mixin.py:188} WARNING - /home/***/.local/lib/python3.12/site-packages/***/task/task_runner/standard_task_runner.py:61 DeprecationWarning: This process (pid=16277) is multi-threaded, use of fork() may lead to deadlocks in the child.
[2024-10-30T00:34:08.246+0000] {standard_task_runner.py:90} INFO - Running: ['***', 'tasks', 'run', 'Stock-Data-Pipeline', 'clean_stock_data', 'manual__2024-10-30T00:33:57.081828+00:00', '--job-id', '258', '--raw', '--subdir', 'DAGS_FOLDER/stock_data_pipeline.py', '--cfg-path', '/tmp/tmpirryp_gs']
[2024-10-30T00:34:08.261+0000] {standard_task_runner.py:63} INFO - Started process 16299 to run task
[2024-10-30T00:34:08.261+0000] {standard_task_runner.py:91} INFO - Job 258: Subtask clean_stock_data
[2024-10-30T00:34:08.299+0000] {logging_mixin.py:188} WARNING - /home/***/.local/lib/python3.12/site-packages/***/settings.py:195 DeprecationWarning: The sql_alchemy_conn option in [core] has been moved to the sql_alchemy_conn option in [database] - the old setting has been used, but please update your config.
[2024-10-30T00:34:08.389+0000] {task_command.py:426} INFO - Running <TaskInstance: Stock-Data-Pipeline.clean_stock_data manual__2024-10-30T00:33:57.081828+00:00 [running]> on host cf1c99cdc1a8
[2024-10-30T00:34:08.549+0000] {taskinstance.py:2648} INFO - Exporting env vars: AIRFLOW_CTX_DAG_OWNER='***' AIRFLOW_CTX_DAG_ID='Stock-Data-Pipeline' AIRFLOW_CTX_TASK_ID='clean_stock_data' AIRFLOW_CTX_EXECUTION_DATE='2024-10-30T00:33:57.081828+00:00' AIRFLOW_CTX_TRY_NUMBER='1' AIRFLOW_CTX_DAG_RUN_ID='manual__2024-10-30T00:33:57.081828+00:00'
[2024-10-30T00:34:08.551+0000] {taskinstance.py:430} INFO - ::endgroup::
[2024-10-30T00:34:08.640+0000] {taskinstance.py:441} INFO - ::group::Post task execution logs
[2024-10-30T00:34:08.642+0000] {taskinstance.py:2905} ERROR - Task failed with exception
Traceback (most recent call last):
  File "/home/airflow/.local/lib/python3.12/site-packages/pandas/core/indexes/base.py", line 3791, in get_loc
    return self._engine.get_loc(casted_key)
           ^^^^^^^^^^^^^^^^^^^^^^^^^^^^^^^^
  File "index.pyx", line 152, in pandas._libs.index.IndexEngine.get_loc
  File "index.pyx", line 181, in pandas._libs.index.IndexEngine.get_loc
  File "pandas/_libs/hashtable_class_helper.pxi", line 7080, in pandas._libs.hashtable.PyObjectHashTable.get_item
  File "pandas/_libs/hashtable_class_helper.pxi", line 7088, in pandas._libs.hashtable.PyObjectHashTable.get_item
KeyError: 'timestamp'

The above exception was the direct cause of the following exception:

Traceback (most recent call last):
  File "/home/airflow/.local/lib/python3.12/site-packages/airflow/models/taskinstance.py", line 465, in _execute_task
    result = _execute_callable(context=context, **execute_callable_kwargs)
             ^^^^^^^^^^^^^^^^^^^^^^^^^^^^^^^^^^^^^^^^^^^^^^^^^^^^^^^^^^^^^
  File "/home/airflow/.local/lib/python3.12/site-packages/airflow/models/taskinstance.py", line 432, in _execute_callable
    return execute_callable(context=context, **execute_callable_kwargs)
           ^^^^^^^^^^^^^^^^^^^^^^^^^^^^^^^^^^^^^^^^^^^^^^^^^^^^^^^^^^^^
  File "/home/airflow/.local/lib/python3.12/site-packages/airflow/models/baseoperator.py", line 401, in wrapper
    return func(self, *args, **kwargs)
           ^^^^^^^^^^^^^^^^^^^^^^^^^^^
  File "/home/airflow/.local/lib/python3.12/site-packages/airflow/operators/python.py", line 235, in execute
    return_value = self.execute_callable()
                   ^^^^^^^^^^^^^^^^^^^^^^^
  File "/home/airflow/.local/lib/python3.12/site-packages/airflow/operators/python.py", line 252, in execute_callable
    return self.python_callable(*self.op_args, **self.op_kwargs)
           ^^^^^^^^^^^^^^^^^^^^^^^^^^^^^^^^^^^^^^^^^^^^^^^^^^^^^
  File "/opt/airflow/dags/utils/stock_data_elt.py", line 42, in clean_stock_data
    df['timestamp'] = pd.to_datetime(df['timestamp'])
                                     ~~^^^^^^^^^^^^^
  File "/home/airflow/.local/lib/python3.12/site-packages/pandas/core/frame.py", line 3893, in __getitem__
    indexer = self.columns.get_loc(key)
              ^^^^^^^^^^^^^^^^^^^^^^^^^
  File "/home/airflow/.local/lib/python3.12/site-packages/pandas/core/indexes/base.py", line 3798, in get_loc
    raise KeyError(key) from err
KeyError: 'timestamp'
[2024-10-30T00:34:08.669+0000] {taskinstance.py:1206} INFO - Marking task as FAILED. dag_id=Stock-Data-Pipeline, task_id=clean_stock_data, run_id=manual__2024-10-30T00:33:57.081828+00:00, execution_date=20241030T003357, start_date=20241030T003408, end_date=20241030T003408
[2024-10-30T00:34:08.681+0000] {standard_task_runner.py:110} ERROR - Failed to execute job 258 for task clean_stock_data ('timestamp'; 16299)
[2024-10-30T00:34:08.721+0000] {local_task_job_runner.py:240} INFO - Task exited with return code 1
[2024-10-30T00:34:08.750+0000] {taskinstance.py:3503} INFO - 0 downstream tasks scheduled from follow-on schedule check
[2024-10-30T00:34:08.758+0000] {local_task_job_runner.py:222} INFO - ::endgroup::
