[2024-10-29T14:30:27.424+0000] {local_task_job_runner.py:120} INFO - ::group::Pre task execution logs
[2024-10-29T14:30:27.685+0000] {taskinstance.py:2076} INFO - Dependencies all met for dep_context=non-requeueable deps ti=<TaskInstance: join_and_feature_engineer_all_data.get_insider_transactions_s3 manual__2024-10-29T14:30:15.385142+00:00 [queued]>
[2024-10-29T14:30:27.732+0000] {taskinstance.py:2076} INFO - Dependencies all met for dep_context=requeueable deps ti=<TaskInstance: join_and_feature_engineer_all_data.get_insider_transactions_s3 manual__2024-10-29T14:30:15.385142+00:00 [queued]>
[2024-10-29T14:30:27.737+0000] {taskinstance.py:2306} INFO - Starting attempt 1 of 1
[2024-10-29T14:30:27.813+0000] {taskinstance.py:2330} INFO - Executing <Task(PythonOperator): get_insider_transactions_s3> on 2024-10-29 14:30:15.385142+00:00
[2024-10-29T14:30:27.883+0000] {logging_mixin.py:188} WARNING - /home/***/.local/lib/python3.12/site-packages/***/task/task_runner/standard_task_runner.py:61 DeprecationWarning: This process (pid=263) is multi-threaded, use of fork() may lead to deadlocks in the child.
[2024-10-29T14:30:27.893+0000] {standard_task_runner.py:63} INFO - Started process 279 to run task
[2024-10-29T14:30:27.896+0000] {standard_task_runner.py:90} INFO - Running: ['***', 'tasks', 'run', 'join_and_feature_engineer_all_data', 'get_insider_transactions_s3', 'manual__2024-10-29T14:30:15.385142+00:00', '--job-id', '112', '--raw', '--subdir', 'DAGS_FOLDER/stock_data_pipelines.py', '--cfg-path', '/tmp/tmpayldv7sz']
[2024-10-29T14:30:27.919+0000] {standard_task_runner.py:91} INFO - Job 112: Subtask get_insider_transactions_s3
[2024-10-29T14:30:28.089+0000] {logging_mixin.py:188} WARNING - /home/***/.local/lib/python3.12/site-packages/***/settings.py:195 DeprecationWarning: The sql_alchemy_conn option in [core] has been moved to the sql_alchemy_conn option in [database] - the old setting has been used, but please update your config.
[2024-10-29T14:30:28.500+0000] {task_command.py:426} INFO - Running <TaskInstance: join_and_feature_engineer_all_data.get_insider_transactions_s3 manual__2024-10-29T14:30:15.385142+00:00 [running]> on host c64098c5955c
[2024-10-29T14:30:28.975+0000] {taskinstance.py:2648} INFO - Exporting env vars: AIRFLOW_CTX_DAG_OWNER='***' AIRFLOW_CTX_DAG_ID='join_and_feature_engineer_all_data' AIRFLOW_CTX_TASK_ID='get_insider_transactions_s3' AIRFLOW_CTX_EXECUTION_DATE='2024-10-29T14:30:15.385142+00:00' AIRFLOW_CTX_TRY_NUMBER='1' AIRFLOW_CTX_DAG_RUN_ID='manual__2024-10-29T14:30:15.385142+00:00'
[2024-10-29T14:30:28.990+0000] {taskinstance.py:430} INFO - ::endgroup::
[2024-10-29T14:30:29.195+0000] {credentials.py:1147} INFO - Found credentials in environment variables.
[2024-10-29T14:30:34.033+0000] {taskinstance.py:441} INFO - ::group::Post task execution logs
[2024-10-29T14:30:34.046+0000] {taskinstance.py:2905} ERROR - Task failed with exception
Traceback (most recent call last):
  File "/home/airflow/.local/lib/python3.12/site-packages/airflow/models/taskinstance.py", line 465, in _execute_task
    result = _execute_callable(context=context, **execute_callable_kwargs)
             ^^^^^^^^^^^^^^^^^^^^^^^^^^^^^^^^^^^^^^^^^^^^^^^^^^^^^^^^^^^^^
  File "/home/airflow/.local/lib/python3.12/site-packages/airflow/models/taskinstance.py", line 432, in _execute_callable
    return execute_callable(context=context, **execute_callable_kwargs)
           ^^^^^^^^^^^^^^^^^^^^^^^^^^^^^^^^^^^^^^^^^^^^^^^^^^^^^^^^^^^^
  File "/home/airflow/.local/lib/python3.12/site-packages/airflow/models/baseoperator.py", line 401, in wrapper
    return func(self, *args, **kwargs)
           ^^^^^^^^^^^^^^^^^^^^^^^^^^^
  File "/home/airflow/.local/lib/python3.12/site-packages/airflow/operators/python.py", line 235, in execute
    return_value = self.execute_callable()
                   ^^^^^^^^^^^^^^^^^^^^^^^
  File "/home/airflow/.local/lib/python3.12/site-packages/airflow/operators/python.py", line 252, in execute_callable
    return self.python_callable(*self.op_args, **self.op_kwargs)
           ^^^^^^^^^^^^^^^^^^^^^^^^^^^^^^^^^^^^^^^^^^^^^^^^^^^^^
  File "/opt/airflow/dags/utils/s3_helper.py", line 61, in get_insider_transaction_data_from_s3
    return get_from_s3(bronze_insider_transaction_data_file_name)
           ^^^^^^^^^^^^^^^^^^^^^^^^^^^^^^^^^^^^^^^^^^^^^^^^^^^^^^
  File "/opt/airflow/dags/utils/s3_helper.py", line 36, in get_from_s3
    s3.download_file(bucket_name, file_name, local_path)
  File "/home/airflow/.local/lib/python3.12/site-packages/boto3/s3/inject.py", line 192, in download_file
    return transfer.download_file(
           ^^^^^^^^^^^^^^^^^^^^^^^
  File "/home/airflow/.local/lib/python3.12/site-packages/boto3/s3/transfer.py", line 405, in download_file
    future.result()
  File "/home/airflow/.local/lib/python3.12/site-packages/s3transfer/futures.py", line 103, in result
    return self._coordinator.result()
           ^^^^^^^^^^^^^^^^^^^^^^^^^^
  File "/home/airflow/.local/lib/python3.12/site-packages/s3transfer/futures.py", line 266, in result
    raise self._exception
  File "/home/airflow/.local/lib/python3.12/site-packages/s3transfer/tasks.py", line 269, in _main
    self._submit(transfer_future=transfer_future, **kwargs)
  File "/home/airflow/.local/lib/python3.12/site-packages/s3transfer/download.py", line 354, in _submit
    response = client.head_object(
               ^^^^^^^^^^^^^^^^^^^
  File "/home/airflow/.local/lib/python3.12/site-packages/botocore/client.py", line 565, in _api_call
    return self._make_api_call(operation_name, kwargs)
           ^^^^^^^^^^^^^^^^^^^^^^^^^^^^^^^^^^^^^^^^^^^
  File "/home/airflow/.local/lib/python3.12/site-packages/botocore/client.py", line 1021, in _make_api_call
    raise error_class(parsed_response, operation_name)
botocore.exceptions.ClientError: An error occurred (403) when calling the HeadObject operation: Forbidden
[2024-10-29T14:30:34.194+0000] {taskinstance.py:1206} INFO - Marking task as FAILED. dag_id=join_and_feature_engineer_all_data, task_id=get_insider_transactions_s3, run_id=manual__2024-10-29T14:30:15.385142+00:00, execution_date=20241029T143015, start_date=20241029T143027, end_date=20241029T143034
[2024-10-29T14:30:34.310+0000] {standard_task_runner.py:110} ERROR - Failed to execute job 112 for task get_insider_transactions_s3 (An error occurred (403) when calling the HeadObject operation: Forbidden; 279)
[2024-10-29T14:30:34.979+0000] {local_task_job_runner.py:240} INFO - Task exited with return code 1
[2024-10-29T14:30:35.096+0000] {local_task_job_runner.py:222} INFO - ::endgroup::
