[2024-10-29T14:54:20.515+0000] {local_task_job_runner.py:120} INFO - ::group::Pre task execution logs
[2024-10-29T14:54:20.550+0000] {taskinstance.py:2076} INFO - Dependencies all met for dep_context=non-requeueable deps ti=<TaskInstance: join_and_feature_engineer_all_data.get_insider_transactions_s3 manual__2024-10-29T14:30:15.385142+00:00 [queued]>
[2024-10-29T14:54:20.557+0000] {taskinstance.py:2076} INFO - Dependencies all met for dep_context=requeueable deps ti=<TaskInstance: join_and_feature_engineer_all_data.get_insider_transactions_s3 manual__2024-10-29T14:30:15.385142+00:00 [queued]>
[2024-10-29T14:54:20.558+0000] {taskinstance.py:2306} INFO - Starting attempt 5 of 5
[2024-10-29T14:54:20.569+0000] {taskinstance.py:2330} INFO - Executing <Task(PythonOperator): get_insider_transactions_s3> on 2024-10-29 14:30:15.385142+00:00
[2024-10-29T14:54:20.584+0000] {logging_mixin.py:188} WARNING - /home/***/.local/lib/python3.12/site-packages/***/task/task_runner/standard_task_runner.py:61 DeprecationWarning: This process (pid=1950) is multi-threaded, use of fork() may lead to deadlocks in the child.
[2024-10-29T14:54:20.587+0000] {standard_task_runner.py:63} INFO - Started process 1965 to run task
[2024-10-29T14:54:20.595+0000] {standard_task_runner.py:90} INFO - Running: ['***', 'tasks', 'run', 'join_and_feature_engineer_all_data', 'get_insider_transactions_s3', 'manual__2024-10-29T14:30:15.385142+00:00', '--job-id', '126', '--raw', '--subdir', 'DAGS_FOLDER/stock_data_pipelines.py', '--cfg-path', '/tmp/tmprjpp76px']
[2024-10-29T14:54:20.600+0000] {standard_task_runner.py:91} INFO - Job 126: Subtask get_insider_transactions_s3
[2024-10-29T14:54:20.628+0000] {logging_mixin.py:188} WARNING - /home/***/.local/lib/python3.12/site-packages/***/settings.py:195 DeprecationWarning: The sql_alchemy_conn option in [core] has been moved to the sql_alchemy_conn option in [database] - the old setting has been used, but please update your config.
[2024-10-29T14:54:20.696+0000] {task_command.py:426} INFO - Running <TaskInstance: join_and_feature_engineer_all_data.get_insider_transactions_s3 manual__2024-10-29T14:30:15.385142+00:00 [running]> on host c64098c5955c
[2024-10-29T14:54:20.822+0000] {taskinstance.py:2648} INFO - Exporting env vars: AIRFLOW_CTX_DAG_OWNER='***' AIRFLOW_CTX_DAG_ID='join_and_feature_engineer_all_data' AIRFLOW_CTX_TASK_ID='get_insider_transactions_s3' AIRFLOW_CTX_EXECUTION_DATE='2024-10-29T14:30:15.385142+00:00' AIRFLOW_CTX_TRY_NUMBER='5' AIRFLOW_CTX_DAG_RUN_ID='manual__2024-10-29T14:30:15.385142+00:00'
[2024-10-29T14:54:20.824+0000] {taskinstance.py:430} INFO - ::endgroup::
[2024-10-29T14:54:20.863+0000] {credentials.py:1147} INFO - Found credentials in environment variables.
[2024-10-29T14:54:22.016+0000] {taskinstance.py:441} INFO - ::group::Post task execution logs
[2024-10-29T14:54:22.019+0000] {taskinstance.py:2905} ERROR - Task failed with exception
Traceback (most recent call last):
  File "/home/airflow/.local/lib/python3.12/site-packages/airflow/models/taskinstance.py", line 465, in _execute_task
    result = _execute_callable(context=context, **execute_callable_kwargs)
             ^^^^^^^^^^^^^^^^^^^^^^^^^^^^^^^^^^^^^^^^^^^^^^^^^^^^^^^^^^^^^
  File "/home/airflow/.local/lib/python3.12/site-packages/airflow/models/taskinstance.py", line 432, in _execute_callable
    return execute_callable(context=context, **execute_callable_kwargs)
           ^^^^^^^^^^^^^^^^^^^^^^^^^^^^^^^^^^^^^^^^^^^^^^^^^^^^^^^^^^^^
  File "/home/airflow/.local/lib/python3.12/site-packages/airflow/models/baseoperator.py", line 401, in wrapper
    return func(self, *args, **kwargs)
           ^^^^^^^^^^^^^^^^^^^^^^^^^^^
  File "/home/airflow/.local/lib/python3.12/site-packages/airflow/operators/python.py", line 235, in execute
    return_value = self.execute_callable()
                   ^^^^^^^^^^^^^^^^^^^^^^^
  File "/home/airflow/.local/lib/python3.12/site-packages/airflow/operators/python.py", line 252, in execute_callable
    return self.python_callable(*self.op_args, **self.op_kwargs)
           ^^^^^^^^^^^^^^^^^^^^^^^^^^^^^^^^^^^^^^^^^^^^^^^^^^^^^
  File "/opt/airflow/dags/utils/s3_helper.py", line 77, in get_insider_transaction_data_from_s3
    return get_from_s3(bronze_insider_transaction_data_file_name)
           ^^^^^^^^^^^^^^^^^^^^^^^^^^^^^^^^^^^^^^^^^^^^^^^^^^^^^^
  File "/opt/airflow/dags/utils/s3_helper.py", line 40, in get_from_s3
    s3.head_object(Bucket=bucket_name, Key=file_name)
  File "/home/airflow/.local/lib/python3.12/site-packages/botocore/client.py", line 565, in _api_call
    return self._make_api_call(operation_name, kwargs)
           ^^^^^^^^^^^^^^^^^^^^^^^^^^^^^^^^^^^^^^^^^^^
  File "/home/airflow/.local/lib/python3.12/site-packages/botocore/client.py", line 1021, in _make_api_call
    raise error_class(parsed_response, operation_name)
botocore.exceptions.ClientError: An error occurred (403) when calling the HeadObject operation: Forbidden
[2024-10-29T14:54:22.055+0000] {taskinstance.py:1206} INFO - Marking task as FAILED. dag_id=join_and_feature_engineer_all_data, task_id=get_insider_transactions_s3, run_id=manual__2024-10-29T14:30:15.385142+00:00, execution_date=20241029T143015, start_date=20241029T145420, end_date=20241029T145422
[2024-10-29T14:54:22.068+0000] {standard_task_runner.py:110} ERROR - Failed to execute job 126 for task get_insider_transactions_s3 (An error occurred (403) when calling the HeadObject operation: Forbidden; 1965)
[2024-10-29T14:54:22.132+0000] {local_task_job_runner.py:240} INFO - Task exited with return code 1
[2024-10-29T14:54:22.161+0000] {taskinstance.py:3503} INFO - 0 downstream tasks scheduled from follow-on schedule check
[2024-10-29T14:54:22.167+0000] {local_task_job_runner.py:222} INFO - ::endgroup::
