[2024-10-29T16:47:00.010+0000] {local_task_job_runner.py:120} INFO - ::group::Pre task execution logs
[2024-10-29T16:47:00.077+0000] {taskinstance.py:2076} INFO - Dependencies all met for dep_context=non-requeueable deps ti=<TaskInstance: join_and_feature_engineer_all_data.get_insider_transactions_s3 manual__2024-10-29T14:30:15.385142+00:00 [queued]>
[2024-10-29T16:47:00.106+0000] {taskinstance.py:2076} INFO - Dependencies all met for dep_context=requeueable deps ti=<TaskInstance: join_and_feature_engineer_all_data.get_insider_transactions_s3 manual__2024-10-29T14:30:15.385142+00:00 [queued]>
[2024-10-29T16:47:00.108+0000] {taskinstance.py:2306} INFO - Starting attempt 27 of 27
[2024-10-29T16:47:00.155+0000] {taskinstance.py:2330} INFO - Executing <Task(PythonOperator): get_insider_transactions_s3> on 2024-10-29 14:30:15.385142+00:00
[2024-10-29T16:47:00.181+0000] {logging_mixin.py:188} WARNING - /home/***/.local/lib/python3.12/site-packages/***/task/task_runner/standard_task_runner.py:61 DeprecationWarning: This process (pid=9918) is multi-threaded, use of fork() may lead to deadlocks in the child.
[2024-10-29T16:47:00.189+0000] {standard_task_runner.py:63} INFO - Started process 9945 to run task
[2024-10-29T16:47:00.206+0000] {standard_task_runner.py:90} INFO - Running: ['***', 'tasks', 'run', 'join_and_feature_engineer_all_data', 'get_insider_transactions_s3', 'manual__2024-10-29T14:30:15.385142+00:00', '--job-id', '190', '--raw', '--subdir', 'DAGS_FOLDER/stock_data_pipelines.py', '--cfg-path', '/tmp/tmpt2cqjr7x']
[2024-10-29T16:47:00.223+0000] {standard_task_runner.py:91} INFO - Job 190: Subtask get_insider_transactions_s3
[2024-10-29T16:47:00.265+0000] {logging_mixin.py:188} WARNING - /home/***/.local/lib/python3.12/site-packages/***/settings.py:195 DeprecationWarning: The sql_alchemy_conn option in [core] has been moved to the sql_alchemy_conn option in [database] - the old setting has been used, but please update your config.
[2024-10-29T16:47:00.477+0000] {task_command.py:426} INFO - Running <TaskInstance: join_and_feature_engineer_all_data.get_insider_transactions_s3 manual__2024-10-29T14:30:15.385142+00:00 [running]> on host c64098c5955c
[2024-10-29T16:47:00.738+0000] {taskinstance.py:2648} INFO - Exporting env vars: AIRFLOW_CTX_DAG_OWNER='***' AIRFLOW_CTX_DAG_ID='join_and_feature_engineer_all_data' AIRFLOW_CTX_TASK_ID='get_insider_transactions_s3' AIRFLOW_CTX_EXECUTION_DATE='2024-10-29T14:30:15.385142+00:00' AIRFLOW_CTX_TRY_NUMBER='27' AIRFLOW_CTX_DAG_RUN_ID='manual__2024-10-29T14:30:15.385142+00:00'
[2024-10-29T16:47:00.744+0000] {taskinstance.py:430} INFO - ::endgroup::
[2024-10-29T16:47:00.861+0000] {credentials.py:1147} INFO - Found credentials in environment variables.
[2024-10-29T16:47:02.366+0000] {logging_mixin.py:188} INFO - 403
[2024-10-29T16:47:02.367+0000] {logging_mixin.py:188} INFO - Forbidden
[2024-10-29T16:47:02.368+0000] {taskinstance.py:441} INFO - ::group::Post task execution logs
[2024-10-29T16:47:02.369+0000] {taskinstance.py:2905} ERROR - Task failed with exception
Traceback (most recent call last):
  File "/home/airflow/.local/lib/python3.12/site-packages/airflow/models/taskinstance.py", line 465, in _execute_task
    result = _execute_callable(context=context, **execute_callable_kwargs)
             ^^^^^^^^^^^^^^^^^^^^^^^^^^^^^^^^^^^^^^^^^^^^^^^^^^^^^^^^^^^^^
  File "/home/airflow/.local/lib/python3.12/site-packages/airflow/models/taskinstance.py", line 432, in _execute_callable
    return execute_callable(context=context, **execute_callable_kwargs)
           ^^^^^^^^^^^^^^^^^^^^^^^^^^^^^^^^^^^^^^^^^^^^^^^^^^^^^^^^^^^^
  File "/home/airflow/.local/lib/python3.12/site-packages/airflow/models/baseoperator.py", line 401, in wrapper
    return func(self, *args, **kwargs)
           ^^^^^^^^^^^^^^^^^^^^^^^^^^^
  File "/home/airflow/.local/lib/python3.12/site-packages/airflow/operators/python.py", line 235, in execute
    return_value = self.execute_callable()
                   ^^^^^^^^^^^^^^^^^^^^^^^
  File "/home/airflow/.local/lib/python3.12/site-packages/airflow/operators/python.py", line 252, in execute_callable
    return self.python_callable(*self.op_args, **self.op_kwargs)
           ^^^^^^^^^^^^^^^^^^^^^^^^^^^^^^^^^^^^^^^^^^^^^^^^^^^^^
  File "/opt/airflow/dags/utils/s3_helper.py", line 71, in get_insider_transaction_data_from_s3
    return get_from_s3(bronze_insider_transaction_data_file_name)
           ^^^^^^^^^^^^^^^^^^^^^^^^^^^^^^^^^^^^^^^^^^^^^^^^^^^^^^
  File "/opt/airflow/dags/utils/s3_helper.py", line 44, in get_from_s3
    raise error
  File "/opt/airflow/dags/utils/s3_helper.py", line 38, in get_from_s3
    s3.download_file(bucket_name, file_name, local_path)
  File "/home/airflow/.local/lib/python3.12/site-packages/boto3/s3/inject.py", line 192, in download_file
    return transfer.download_file(
           ^^^^^^^^^^^^^^^^^^^^^^^
  File "/home/airflow/.local/lib/python3.12/site-packages/boto3/s3/transfer.py", line 405, in download_file
    future.result()
  File "/home/airflow/.local/lib/python3.12/site-packages/s3transfer/futures.py", line 103, in result
    return self._coordinator.result()
           ^^^^^^^^^^^^^^^^^^^^^^^^^^
  File "/home/airflow/.local/lib/python3.12/site-packages/s3transfer/futures.py", line 266, in result
    raise self._exception
  File "/home/airflow/.local/lib/python3.12/site-packages/s3transfer/tasks.py", line 269, in _main
    self._submit(transfer_future=transfer_future, **kwargs)
  File "/home/airflow/.local/lib/python3.12/site-packages/s3transfer/download.py", line 354, in _submit
    response = client.head_object(
               ^^^^^^^^^^^^^^^^^^^
  File "/home/airflow/.local/lib/python3.12/site-packages/botocore/client.py", line 565, in _api_call
    return self._make_api_call(operation_name, kwargs)
           ^^^^^^^^^^^^^^^^^^^^^^^^^^^^^^^^^^^^^^^^^^^
  File "/home/airflow/.local/lib/python3.12/site-packages/botocore/client.py", line 1021, in _make_api_call
    raise error_class(parsed_response, operation_name)
botocore.exceptions.ClientError: An error occurred (403) when calling the HeadObject operation: Forbidden
[2024-10-29T16:47:02.394+0000] {taskinstance.py:1206} INFO - Marking task as FAILED. dag_id=join_and_feature_engineer_all_data, task_id=get_insider_transactions_s3, run_id=manual__2024-10-29T14:30:15.385142+00:00, execution_date=20241029T143015, start_date=20241029T164700, end_date=20241029T164702
[2024-10-29T16:47:02.432+0000] {standard_task_runner.py:110} ERROR - Failed to execute job 190 for task get_insider_transactions_s3 (An error occurred (403) when calling the HeadObject operation: Forbidden; 9945)
[2024-10-29T16:47:02.496+0000] {local_task_job_runner.py:240} INFO - Task exited with return code 1
[2024-10-29T16:47:02.539+0000] {local_task_job_runner.py:222} INFO - ::endgroup::
