[2024-10-30T15:30:08.319+0000] {local_task_job_runner.py:120} INFO - ::group::Pre task execution logs
[2024-10-30T15:30:08.345+0000] {taskinstance.py:2076} INFO - Dependencies all met for dep_context=non-requeueable deps ti=<TaskInstance: Predice-Stock-ML-Pipeline.store_ml_model_in_s3 manual__2024-10-30T14:27:23.134497+00:00 [queued]>
[2024-10-30T15:30:08.350+0000] {taskinstance.py:2076} INFO - Dependencies all met for dep_context=requeueable deps ti=<TaskInstance: Predice-Stock-ML-Pipeline.store_ml_model_in_s3 manual__2024-10-30T14:27:23.134497+00:00 [queued]>
[2024-10-30T15:30:08.350+0000] {taskinstance.py:2306} INFO - Starting attempt 5 of 5
[2024-10-30T15:30:08.357+0000] {taskinstance.py:2330} INFO - Executing <Task(PythonOperator): store_ml_model_in_s3> on 2024-10-30 14:27:23.134497+00:00
[2024-10-30T15:30:08.365+0000] {logging_mixin.py:188} WARNING - /home/***/.local/lib/python3.12/site-packages/***/task/task_runner/standard_task_runner.py:61 DeprecationWarning: This process (pid=6143) is multi-threaded, use of fork() may lead to deadlocks in the child.
[2024-10-30T15:30:08.367+0000] {standard_task_runner.py:63} INFO - Started process 6148 to run task
[2024-10-30T15:30:08.366+0000] {standard_task_runner.py:90} INFO - Running: ['***', 'tasks', 'run', 'Predice-Stock-ML-Pipeline', 'store_ml_model_in_s3', 'manual__2024-10-30T14:27:23.134497+00:00', '--job-id', '336', '--raw', '--subdir', 'DAGS_FOLDER/stock_and_sentiment_ml_pipeline.py', '--cfg-path', '/tmp/tmpck1oam48']
[2024-10-30T15:30:08.369+0000] {standard_task_runner.py:91} INFO - Job 336: Subtask store_ml_model_in_s3
[2024-10-30T15:30:08.382+0000] {logging_mixin.py:188} WARNING - /home/***/.local/lib/python3.12/site-packages/***/settings.py:195 DeprecationWarning: The sql_alchemy_conn option in [core] has been moved to the sql_alchemy_conn option in [database] - the old setting has been used, but please update your config.
[2024-10-30T15:30:08.412+0000] {task_command.py:426} INFO - Running <TaskInstance: Predice-Stock-ML-Pipeline.store_ml_model_in_s3 manual__2024-10-30T14:27:23.134497+00:00 [running]> on host cf1c99cdc1a8
[2024-10-30T15:30:08.609+0000] {taskinstance.py:2648} INFO - Exporting env vars: AIRFLOW_CTX_DAG_OWNER='***' AIRFLOW_CTX_DAG_ID='Predice-Stock-ML-Pipeline' AIRFLOW_CTX_TASK_ID='store_ml_model_in_s3' AIRFLOW_CTX_EXECUTION_DATE='2024-10-30T14:27:23.134497+00:00' AIRFLOW_CTX_TRY_NUMBER='5' AIRFLOW_CTX_DAG_RUN_ID='manual__2024-10-30T14:27:23.134497+00:00'
[2024-10-30T15:30:08.610+0000] {taskinstance.py:430} INFO - ::endgroup::
[2024-10-30T15:30:08.627+0000] {logging_mixin.py:188} INFO - <class 'tuple'>
[2024-10-30T15:30:08.628+0000] {logging_mixin.py:188} INFO - random_forest
[2024-10-30T15:30:08.629+0000] {logging_mixin.py:188} INFO - hist_gradient_boosting
[2024-10-30T15:30:08.629+0000] {taskinstance.py:441} INFO - ::group::Post task execution logs
[2024-10-30T15:30:08.630+0000] {taskinstance.py:2905} ERROR - Task failed with exception
Traceback (most recent call last):
  File "/home/airflow/.local/lib/python3.12/site-packages/airflow/models/taskinstance.py", line 465, in _execute_task
    result = _execute_callable(context=context, **execute_callable_kwargs)
             ^^^^^^^^^^^^^^^^^^^^^^^^^^^^^^^^^^^^^^^^^^^^^^^^^^^^^^^^^^^^^
  File "/home/airflow/.local/lib/python3.12/site-packages/airflow/models/taskinstance.py", line 432, in _execute_callable
    return execute_callable(context=context, **execute_callable_kwargs)
           ^^^^^^^^^^^^^^^^^^^^^^^^^^^^^^^^^^^^^^^^^^^^^^^^^^^^^^^^^^^^
  File "/home/airflow/.local/lib/python3.12/site-packages/airflow/models/baseoperator.py", line 401, in wrapper
    return func(self, *args, **kwargs)
           ^^^^^^^^^^^^^^^^^^^^^^^^^^^
  File "/home/airflow/.local/lib/python3.12/site-packages/airflow/operators/python.py", line 235, in execute
    return_value = self.execute_callable()
                   ^^^^^^^^^^^^^^^^^^^^^^^
  File "/home/airflow/.local/lib/python3.12/site-packages/airflow/operators/python.py", line 252, in execute_callable
    return self.python_callable(*self.op_args, **self.op_kwargs)
           ^^^^^^^^^^^^^^^^^^^^^^^^^^^^^^^^^^^^^^^^^^^^^^^^^^^^^
  File "/opt/airflow/dags/utils/s3_helper.py", line 118, in store_ml_model_s3
    model_rf = models['random_forest']
               ~~~~~~^^^^^^^^^^^^^^^^^
TypeError: tuple indices must be integers or slices, not str
[2024-10-30T15:30:08.641+0000] {taskinstance.py:1206} INFO - Marking task as FAILED. dag_id=Predice-Stock-ML-Pipeline, task_id=store_ml_model_in_s3, run_id=manual__2024-10-30T14:27:23.134497+00:00, execution_date=20241030T142723, start_date=20241030T153008, end_date=20241030T153008
[2024-10-30T15:30:08.648+0000] {standard_task_runner.py:110} ERROR - Failed to execute job 336 for task store_ml_model_in_s3 (tuple indices must be integers or slices, not str; 6148)
[2024-10-30T15:30:08.716+0000] {local_task_job_runner.py:240} INFO - Task exited with return code 1
[2024-10-30T15:30:08.731+0000] {taskinstance.py:3503} INFO - 0 downstream tasks scheduled from follow-on schedule check
[2024-10-30T15:30:08.733+0000] {local_task_job_runner.py:222} INFO - ::endgroup::
